INFO:discord.client:logging in using static token
INFO:slack_bolt.AsyncApp:A new session (s_138305681271) has been established
INFO:slack_bolt.AsyncApp:Bolt app is running!
INFO:discord.gateway:Shard ID None has connected to Gateway (Session ID: 13ffb623d00a1563f010720fdd12959a).
INFO:discord.client:logging in using static token
INFO:slack_bolt.AsyncApp:A new session (s_132089722743) has been established
INFO:slack_bolt.AsyncApp:Bolt app is running!
INFO:discord.gateway:Shard ID None has connected to Gateway (Session ID: f0628e7ce729e102a862e581514caba9).
INFO:discord.client:logging in using static token
INFO:slack_bolt.AsyncApp:A new session (s_106366224268) has been established
INFO:slack_bolt.AsyncApp:Bolt app is running!
INFO:discord.gateway:Shard ID None has connected to Gateway (Session ID: 81f6e23b75d13d29b356859063ccc10b).
INFO:discord.client:logging in using static token
INFO:slack_bolt.AsyncApp:A new session (s_147724879756) has been established
INFO:slack_bolt.AsyncApp:Bolt app is running!
INFO:discord.gateway:Shard ID None has connected to Gateway (Session ID: 0b2faa92a13a1badda23678e0cc4d47a).
INFO:discord.client:logging in using static token
INFO:slack_bolt.AsyncApp:A new session (s_100695762849) has been established
INFO:slack_bolt.AsyncApp:Bolt app is running!
INFO:discord.gateway:Shard ID None has connected to Gateway (Session ID: 0c22dcb0093c6f306ec8caa09be3300c).
INFO:discord.client:logging in using static token
INFO:slack_bolt.AsyncApp:A new session (s_123257433891) has been established
INFO:slack_bolt.AsyncApp:Bolt app is running!
INFO:discord.gateway:Shard ID None has connected to Gateway (Session ID: 11b29e4f2f0b7ecbc591f8894df91cf2).
INFO:discord.client:logging in using static token
INFO:slack_bolt.AsyncApp:A new session (s_138318528291) has been established
INFO:slack_bolt.AsyncApp:Bolt app is running!
INFO:discord.gateway:Shard ID None has connected to Gateway (Session ID: 179c48cf8557ffa42d0201a5ec869c6d).
INFO:discord.client:logging in using static token
INFO:slack_bolt.AsyncApp:A new session (s_154786484003) has been established
INFO:slack_bolt.AsyncApp:Bolt app is running!
INFO:discord.gateway:Shard ID None has connected to Gateway (Session ID: 798f42dc70af2b84d0972871acd7242c).
ERROR:discord.ext.commands.bot:Ignoring exception in command None
discord.ext.commands.errors.CommandNotFound: Command "Delete" is not found
ERROR:discord.ext.commands.bot:Ignoring exception in command None
discord.ext.commands.errors.CommandNotFound: Command "purge" is not found
ERROR:discord.ext.commands.bot:Ignoring exception in command Clear
Traceback (most recent call last):
  File "C:\Users\chike\AppData\Local\Packages\PythonSoftwareFoundation.Python.3.13_qbz5n2kfra8p0\LocalCache\local-packages\Python313\site-packages\discord\ext\commands\bot.py", line 1366, in invoke
    await ctx.command.invoke(ctx)
  File "C:\Users\chike\AppData\Local\Packages\PythonSoftwareFoundation.Python.3.13_qbz5n2kfra8p0\LocalCache\local-packages\Python313\site-packages\discord\ext\commands\core.py", line 1021, in invoke
    await self.prepare(ctx)
  File "C:\Users\chike\AppData\Local\Packages\PythonSoftwareFoundation.Python.3.13_qbz5n2kfra8p0\LocalCache\local-packages\Python313\site-packages\discord\ext\commands\core.py", line 925, in prepare
    if not await self.can_run(ctx):
           ^^^^^^^^^^^^^^^^^^^^^^^
  File "C:\Users\chike\AppData\Local\Packages\PythonSoftwareFoundation.Python.3.13_qbz5n2kfra8p0\LocalCache\local-packages\Python313\site-packages\discord\ext\commands\core.py", line 1288, in can_run
    return await discord.utils.async_all(predicate(ctx) for predicate in predicates)  # type: ignore
           ^^^^^^^^^^^^^^^^^^^^^^^^^^^^^^^^^^^^^^^^^^^^^^^^^^^^^^^^^^^^^^^^^^^^^^^^^
  File "C:\Users\chike\AppData\Local\Packages\PythonSoftwareFoundation.Python.3.13_qbz5n2kfra8p0\LocalCache\local-packages\Python313\site-packages\discord\utils.py", line 725, in async_all
    for elem in gen:
                ^^^
  File "C:\Users\chike\AppData\Local\Packages\PythonSoftwareFoundation.Python.3.13_qbz5n2kfra8p0\LocalCache\local-packages\Python313\site-packages\discord\ext\commands\core.py", line 1288, in <genexpr>
    return await discord.utils.async_all(predicate(ctx) for predicate in predicates)  # type: ignore
                                         ~~~~~~~~~^^^^^
  File "C:\Users\chike\AppData\Local\Packages\PythonSoftwareFoundation.Python.3.13_qbz5n2kfra8p0\LocalCache\local-packages\Python313\site-packages\discord\ext\commands\core.py", line 2051, in predicate
    raise MissingRole(item)
discord.ext.commands.errors.MissingRole: Role <module 'SuperAdmin' from 'D:\\testing\\DiscordBot\\SuperAdmin.py'> is required to run this command.
ERROR:discord.ext.commands.bot:Ignoring exception in command Clear
Traceback (most recent call last):
  File "C:\Users\chike\AppData\Local\Packages\PythonSoftwareFoundation.Python.3.13_qbz5n2kfra8p0\LocalCache\local-packages\Python313\site-packages\discord\ext\commands\bot.py", line 1366, in invoke
    await ctx.command.invoke(ctx)
  File "C:\Users\chike\AppData\Local\Packages\PythonSoftwareFoundation.Python.3.13_qbz5n2kfra8p0\LocalCache\local-packages\Python313\site-packages\discord\ext\commands\core.py", line 1021, in invoke
    await self.prepare(ctx)
  File "C:\Users\chike\AppData\Local\Packages\PythonSoftwareFoundation.Python.3.13_qbz5n2kfra8p0\LocalCache\local-packages\Python313\site-packages\discord\ext\commands\core.py", line 925, in prepare
    if not await self.can_run(ctx):
           ^^^^^^^^^^^^^^^^^^^^^^^
  File "C:\Users\chike\AppData\Local\Packages\PythonSoftwareFoundation.Python.3.13_qbz5n2kfra8p0\LocalCache\local-packages\Python313\site-packages\discord\ext\commands\core.py", line 1288, in can_run
    return await discord.utils.async_all(predicate(ctx) for predicate in predicates)  # type: ignore
           ^^^^^^^^^^^^^^^^^^^^^^^^^^^^^^^^^^^^^^^^^^^^^^^^^^^^^^^^^^^^^^^^^^^^^^^^^
  File "C:\Users\chike\AppData\Local\Packages\PythonSoftwareFoundation.Python.3.13_qbz5n2kfra8p0\LocalCache\local-packages\Python313\site-packages\discord\utils.py", line 725, in async_all
    for elem in gen:
                ^^^
  File "C:\Users\chike\AppData\Local\Packages\PythonSoftwareFoundation.Python.3.13_qbz5n2kfra8p0\LocalCache\local-packages\Python313\site-packages\discord\ext\commands\core.py", line 1288, in <genexpr>
    return await discord.utils.async_all(predicate(ctx) for predicate in predicates)  # type: ignore
                                         ~~~~~~~~~^^^^^
  File "C:\Users\chike\AppData\Local\Packages\PythonSoftwareFoundation.Python.3.13_qbz5n2kfra8p0\LocalCache\local-packages\Python313\site-packages\discord\ext\commands\core.py", line 2051, in predicate
    raise MissingRole(item)
discord.ext.commands.errors.MissingRole: Role <module 'SuperAdmin' from 'D:\\testing\\DiscordBot\\SuperAdmin.py'> is required to run this command.
ERROR:discord.ext.commands.bot:Ignoring exception in command Clear
Traceback (most recent call last):
  File "C:\Users\chike\AppData\Local\Packages\PythonSoftwareFoundation.Python.3.13_qbz5n2kfra8p0\LocalCache\local-packages\Python313\site-packages\discord\ext\commands\bot.py", line 1366, in invoke
    await ctx.command.invoke(ctx)
  File "C:\Users\chike\AppData\Local\Packages\PythonSoftwareFoundation.Python.3.13_qbz5n2kfra8p0\LocalCache\local-packages\Python313\site-packages\discord\ext\commands\core.py", line 1021, in invoke
    await self.prepare(ctx)
  File "C:\Users\chike\AppData\Local\Packages\PythonSoftwareFoundation.Python.3.13_qbz5n2kfra8p0\LocalCache\local-packages\Python313\site-packages\discord\ext\commands\core.py", line 925, in prepare
    if not await self.can_run(ctx):
           ^^^^^^^^^^^^^^^^^^^^^^^
  File "C:\Users\chike\AppData\Local\Packages\PythonSoftwareFoundation.Python.3.13_qbz5n2kfra8p0\LocalCache\local-packages\Python313\site-packages\discord\ext\commands\core.py", line 1288, in can_run
    return await discord.utils.async_all(predicate(ctx) for predicate in predicates)  # type: ignore
           ^^^^^^^^^^^^^^^^^^^^^^^^^^^^^^^^^^^^^^^^^^^^^^^^^^^^^^^^^^^^^^^^^^^^^^^^^
  File "C:\Users\chike\AppData\Local\Packages\PythonSoftwareFoundation.Python.3.13_qbz5n2kfra8p0\LocalCache\local-packages\Python313\site-packages\discord\utils.py", line 725, in async_all
    for elem in gen:
                ^^^
  File "C:\Users\chike\AppData\Local\Packages\PythonSoftwareFoundation.Python.3.13_qbz5n2kfra8p0\LocalCache\local-packages\Python313\site-packages\discord\ext\commands\core.py", line 1288, in <genexpr>
    return await discord.utils.async_all(predicate(ctx) for predicate in predicates)  # type: ignore
                                         ~~~~~~~~~^^^^^
  File "C:\Users\chike\AppData\Local\Packages\PythonSoftwareFoundation.Python.3.13_qbz5n2kfra8p0\LocalCache\local-packages\Python313\site-packages\discord\ext\commands\core.py", line 2051, in predicate
    raise MissingRole(item)
discord.ext.commands.errors.MissingRole: Role <module 'SuperAdmin' from 'D:\\testing\\DiscordBot\\SuperAdmin.py'> is required to run this command.
INFO:discord.client:logging in using static token
INFO:slack_bolt.AsyncApp:A new session (s_176832524067) has been established
INFO:slack_bolt.AsyncApp:Bolt app is running!
INFO:discord.gateway:Shard ID None has connected to Gateway (Session ID: 7e1f0ddcb28e65b360a657e1f2f549a8).
ERROR:discord.ext.commands.bot:Ignoring exception in command Clear
Traceback (most recent call last):
  File "C:\Users\chike\AppData\Local\Packages\PythonSoftwareFoundation.Python.3.13_qbz5n2kfra8p0\LocalCache\local-packages\Python313\site-packages\discord\ext\commands\bot.py", line 1366, in invoke
    await ctx.command.invoke(ctx)
  File "C:\Users\chike\AppData\Local\Packages\PythonSoftwareFoundation.Python.3.13_qbz5n2kfra8p0\LocalCache\local-packages\Python313\site-packages\discord\ext\commands\core.py", line 1021, in invoke
    await self.prepare(ctx)
  File "C:\Users\chike\AppData\Local\Packages\PythonSoftwareFoundation.Python.3.13_qbz5n2kfra8p0\LocalCache\local-packages\Python313\site-packages\discord\ext\commands\core.py", line 938, in prepare
    await self._parse_arguments(ctx)
  File "C:\Users\chike\AppData\Local\Packages\PythonSoftwareFoundation.Python.3.13_qbz5n2kfra8p0\LocalCache\local-packages\Python313\site-packages\discord\ext\commands\core.py", line 845, in _parse_arguments
    transformed = await self.transform(ctx, param, attachments)
                  ^^^^^^^^^^^^^^^^^^^^^^^^^^^^^^^^^^^^^^^^^^^^^
  File "C:\Users\chike\AppData\Local\Packages\PythonSoftwareFoundation.Python.3.13_qbz5n2kfra8p0\LocalCache\local-packages\Python313\site-packages\discord\ext\commands\core.py", line 697, in transform
    raise MissingRequiredArgument(param)
discord.ext.commands.errors.MissingRequiredArgument: amount is a required argument that is missing.
INFO:discord.client:logging in using static token
INFO:slack_bolt.AsyncApp:A new session (s_119460966179) has been established
INFO:slack_bolt.AsyncApp:Bolt app is running!
INFO:discord.gateway:Shard ID None has connected to Gateway (Session ID: b82d18d10ffe21495e502f02a9ddaa90).
ERROR:discord.ext.commands.bot:Ignoring exception in command Clear
Traceback (most recent call last):
  File "C:\Users\chike\AppData\Local\Packages\PythonSoftwareFoundation.Python.3.13_qbz5n2kfra8p0\LocalCache\local-packages\Python313\site-packages\discord\ext\commands\bot.py", line 1366, in invoke
    await ctx.command.invoke(ctx)
  File "C:\Users\chike\AppData\Local\Packages\PythonSoftwareFoundation.Python.3.13_qbz5n2kfra8p0\LocalCache\local-packages\Python313\site-packages\discord\ext\commands\core.py", line 1021, in invoke
    await self.prepare(ctx)
  File "C:\Users\chike\AppData\Local\Packages\PythonSoftwareFoundation.Python.3.13_qbz5n2kfra8p0\LocalCache\local-packages\Python313\site-packages\discord\ext\commands\core.py", line 925, in prepare
    if not await self.can_run(ctx):
           ^^^^^^^^^^^^^^^^^^^^^^^
  File "C:\Users\chike\AppData\Local\Packages\PythonSoftwareFoundation.Python.3.13_qbz5n2kfra8p0\LocalCache\local-packages\Python313\site-packages\discord\ext\commands\core.py", line 1288, in can_run
    return await discord.utils.async_all(predicate(ctx) for predicate in predicates)  # type: ignore
           ^^^^^^^^^^^^^^^^^^^^^^^^^^^^^^^^^^^^^^^^^^^^^^^^^^^^^^^^^^^^^^^^^^^^^^^^^
  File "C:\Users\chike\AppData\Local\Packages\PythonSoftwareFoundation.Python.3.13_qbz5n2kfra8p0\LocalCache\local-packages\Python313\site-packages\discord\utils.py", line 725, in async_all
    for elem in gen:
                ^^^
  File "C:\Users\chike\AppData\Local\Packages\PythonSoftwareFoundation.Python.3.13_qbz5n2kfra8p0\LocalCache\local-packages\Python313\site-packages\discord\ext\commands\core.py", line 1288, in <genexpr>
    return await discord.utils.async_all(predicate(ctx) for predicate in predicates)  # type: ignore
                                         ~~~~~~~~~^^^^^
  File "C:\Users\chike\AppData\Local\Packages\PythonSoftwareFoundation.Python.3.13_qbz5n2kfra8p0\LocalCache\local-packages\Python313\site-packages\discord\ext\commands\core.py", line 2051, in predicate
    raise MissingRole(item)
discord.ext.commands.errors.MissingRole: Role <module 'SuperAdmin' from 'D:\\testing\\DiscordBot\\SuperAdmin.py'> is required to run this command.
ERROR:discord.ext.commands.bot:Ignoring exception in command Clear
Traceback (most recent call last):
  File "C:\Users\chike\AppData\Local\Packages\PythonSoftwareFoundation.Python.3.13_qbz5n2kfra8p0\LocalCache\local-packages\Python313\site-packages\discord\ext\commands\bot.py", line 1366, in invoke
    await ctx.command.invoke(ctx)
  File "C:\Users\chike\AppData\Local\Packages\PythonSoftwareFoundation.Python.3.13_qbz5n2kfra8p0\LocalCache\local-packages\Python313\site-packages\discord\ext\commands\core.py", line 1021, in invoke
    await self.prepare(ctx)
  File "C:\Users\chike\AppData\Local\Packages\PythonSoftwareFoundation.Python.3.13_qbz5n2kfra8p0\LocalCache\local-packages\Python313\site-packages\discord\ext\commands\core.py", line 925, in prepare
    if not await self.can_run(ctx):
           ^^^^^^^^^^^^^^^^^^^^^^^
  File "C:\Users\chike\AppData\Local\Packages\PythonSoftwareFoundation.Python.3.13_qbz5n2kfra8p0\LocalCache\local-packages\Python313\site-packages\discord\ext\commands\core.py", line 1288, in can_run
    return await discord.utils.async_all(predicate(ctx) for predicate in predicates)  # type: ignore
           ^^^^^^^^^^^^^^^^^^^^^^^^^^^^^^^^^^^^^^^^^^^^^^^^^^^^^^^^^^^^^^^^^^^^^^^^^
  File "C:\Users\chike\AppData\Local\Packages\PythonSoftwareFoundation.Python.3.13_qbz5n2kfra8p0\LocalCache\local-packages\Python313\site-packages\discord\utils.py", line 725, in async_all
    for elem in gen:
                ^^^
  File "C:\Users\chike\AppData\Local\Packages\PythonSoftwareFoundation.Python.3.13_qbz5n2kfra8p0\LocalCache\local-packages\Python313\site-packages\discord\ext\commands\core.py", line 1288, in <genexpr>
    return await discord.utils.async_all(predicate(ctx) for predicate in predicates)  # type: ignore
                                         ~~~~~~~~~^^^^^
  File "C:\Users\chike\AppData\Local\Packages\PythonSoftwareFoundation.Python.3.13_qbz5n2kfra8p0\LocalCache\local-packages\Python313\site-packages\discord\ext\commands\core.py", line 2051, in predicate
    raise MissingRole(item)
discord.ext.commands.errors.MissingRole: Role <module 'SuperAdmin' from 'D:\\testing\\DiscordBot\\SuperAdmin.py'> is required to run this command.
INFO:discord.client:logging in using static token
INFO:slack_bolt.AsyncApp:A new session (s_128368631587) has been established
INFO:slack_bolt.AsyncApp:Bolt app is running!
INFO:discord.gateway:Shard ID None has connected to Gateway (Session ID: 8a9aa0cbd12a126922b41cf0a51e6ea1).
ERROR:discord.ext.commands.bot:Ignoring exception in command Clear
Traceback (most recent call last):
  File "C:\Users\chike\AppData\Local\Packages\PythonSoftwareFoundation.Python.3.13_qbz5n2kfra8p0\LocalCache\local-packages\Python313\site-packages\discord\ext\commands\bot.py", line 1366, in invoke
    await ctx.command.invoke(ctx)
  File "C:\Users\chike\AppData\Local\Packages\PythonSoftwareFoundation.Python.3.13_qbz5n2kfra8p0\LocalCache\local-packages\Python313\site-packages\discord\ext\commands\core.py", line 1021, in invoke
    await self.prepare(ctx)
  File "C:\Users\chike\AppData\Local\Packages\PythonSoftwareFoundation.Python.3.13_qbz5n2kfra8p0\LocalCache\local-packages\Python313\site-packages\discord\ext\commands\core.py", line 925, in prepare
    if not await self.can_run(ctx):
           ^^^^^^^^^^^^^^^^^^^^^^^
  File "C:\Users\chike\AppData\Local\Packages\PythonSoftwareFoundation.Python.3.13_qbz5n2kfra8p0\LocalCache\local-packages\Python313\site-packages\discord\ext\commands\core.py", line 1288, in can_run
    return await discord.utils.async_all(predicate(ctx) for predicate in predicates)  # type: ignore
           ^^^^^^^^^^^^^^^^^^^^^^^^^^^^^^^^^^^^^^^^^^^^^^^^^^^^^^^^^^^^^^^^^^^^^^^^^
  File "C:\Users\chike\AppData\Local\Packages\PythonSoftwareFoundation.Python.3.13_qbz5n2kfra8p0\LocalCache\local-packages\Python313\site-packages\discord\utils.py", line 725, in async_all
    for elem in gen:
                ^^^
  File "C:\Users\chike\AppData\Local\Packages\PythonSoftwareFoundation.Python.3.13_qbz5n2kfra8p0\LocalCache\local-packages\Python313\site-packages\discord\ext\commands\core.py", line 1288, in <genexpr>
    return await discord.utils.async_all(predicate(ctx) for predicate in predicates)  # type: ignore
                                         ~~~~~~~~~^^^^^
  File "C:\Users\chike\AppData\Local\Packages\PythonSoftwareFoundation.Python.3.13_qbz5n2kfra8p0\LocalCache\local-packages\Python313\site-packages\discord\ext\commands\core.py", line 2051, in predicate
    raise MissingRole(item)
discord.ext.commands.errors.MissingRole: Role <module 'SuperAdmin' from 'D:\\testing\\DiscordBot\\SuperAdmin.py'> is required to run this command.
INFO:discord.client:logging in using static token
INFO:slack_bolt.AsyncApp:A new session (s_84448988963) has been established
INFO:slack_bolt.AsyncApp:Bolt app is running!
INFO:discord.gateway:Shard ID None has connected to Gateway (Session ID: 0c77cdb169c51a32a825fbca43a20c3d).
INFO:discord.client:logging in using static token
INFO:slack_bolt.AsyncApp:A new session (s_94571607843) has been established
INFO:slack_bolt.AsyncApp:Bolt app is running!
INFO:discord.gateway:Shard ID None has connected to Gateway (Session ID: c297313cccab7442c96e88dd5b47b9c1).
INFO:discord.client:logging in using static token
INFO:slack_bolt.AsyncApp:A new session (s_124457447203) has been established
INFO:slack_bolt.AsyncApp:Bolt app is running!
INFO:discord.gateway:Shard ID None has connected to Gateway (Session ID: 11e29f9f69ee91d65402524dc2754db0).
INFO:discord.client:logging in using static token
INFO:slack_bolt.AsyncApp:A new session (s_136301096739) has been established
INFO:slack_bolt.AsyncApp:Bolt app is running!
INFO:discord.gateway:Shard ID None has connected to Gateway (Session ID: 385dda9241a994c139c4d8125fe8096e).
INFO:discord.client:logging in using static token
INFO:slack_bolt.AsyncApp:A new session (s_157797396259) has been established
INFO:slack_bolt.AsyncApp:Bolt app is running!
INFO:discord.gateway:Shard ID None has connected to Gateway (Session ID: 655e26b12c4d3348e7c594ccaf2d2c60).
INFO:discord.client:logging in using static token
INFO:slack_bolt.AsyncApp:A new session (s_165538557731) has been established
INFO:slack_bolt.AsyncApp:Bolt app is running!
INFO:discord.gateway:Shard ID None has connected to Gateway (Session ID: cba10518a3841d892208988068a73cf2).
ERROR:discord.ext.commands.bot:Ignoring exception in command DeleteCategory
Traceback (most recent call last):
  File "C:\Users\chike\AppData\Local\Packages\PythonSoftwareFoundation.Python.3.13_qbz5n2kfra8p0\LocalCache\local-packages\Python313\site-packages\discord\ext\commands\core.py", line 235, in wrapped
    ret = await coro(*args, **kwargs)
          ^^^^^^^^^^^^^^^^^^^^^^^^^^^
  File "D:\testing\DiscordBot\main.py", line 100, in DeleteCategory
    confirm = await bot.wait_for("message", check=lambda m: m.author == message.author and m.channel == message.channel)
              ^^^^^^^^^^^^^^^^^^^^^^^^^^^^^^^^^^^^^^^^^^^^^^^^^^^^^^^^^^^^^^^^^^^^^^^^^^^^^^^^^^^^^^^^^^^^^^^^^^^^^^^^^^
  File "C:\Program Files\WindowsApps\PythonSoftwareFoundation.Python.3.13_3.13.1520.0_x64__qbz5n2kfra8p0\Lib\asyncio\tasks.py", line 507, in wait_for
    return await fut
           ^^^^^^^^^
  File "C:\Users\chike\AppData\Local\Packages\PythonSoftwareFoundation.Python.3.13_qbz5n2kfra8p0\LocalCache\local-packages\Python313\site-packages\discord\client.py", line 514, in dispatch
    result = condition(*args)
  File "D:\testing\DiscordBot\main.py", line 100, in <lambda>
    confirm = await bot.wait_for("message", check=lambda m: m.author == message.author and m.channel == message.channel)
                                                                        ^^^^^^^^^^^^^^
AttributeError: 'str' object has no attribute 'author'

The above exception was the direct cause of the following exception:

Traceback (most recent call last):
  File "C:\Users\chike\AppData\Local\Packages\PythonSoftwareFoundation.Python.3.13_qbz5n2kfra8p0\LocalCache\local-packages\Python313\site-packages\discord\ext\commands\bot.py", line 1366, in invoke
    await ctx.command.invoke(ctx)
  File "C:\Users\chike\AppData\Local\Packages\PythonSoftwareFoundation.Python.3.13_qbz5n2kfra8p0\LocalCache\local-packages\Python313\site-packages\discord\ext\commands\core.py", line 1029, in invoke
    await injected(*ctx.args, **ctx.kwargs)  # type: ignore
    ^^^^^^^^^^^^^^^^^^^^^^^^^^^^^^^^^^^^^^^
  File "C:\Users\chike\AppData\Local\Packages\PythonSoftwareFoundation.Python.3.13_qbz5n2kfra8p0\LocalCache\local-packages\Python313\site-packages\discord\ext\commands\core.py", line 244, in wrapped
    raise CommandInvokeError(exc) from exc
discord.ext.commands.errors.CommandInvokeError: Command raised an exception: AttributeError: 'str' object has no attribute 'author'
INFO:discord.client:logging in using static token
INFO:slack_bolt.AsyncApp:A new session (s_128476344099) has been established
INFO:slack_bolt.AsyncApp:Bolt app is running!
INFO:discord.gateway:Shard ID None has connected to Gateway (Session ID: 00a9f74ce239caab9e7ce8a4fd345db8).
ERROR:discord.ext.commands.bot:Ignoring exception in command DeleteCategory
Traceback (most recent call last):
  File "C:\Users\chike\AppData\Local\Packages\PythonSoftwareFoundation.Python.3.13_qbz5n2kfra8p0\LocalCache\local-packages\Python313\site-packages\discord\ext\commands\core.py", line 235, in wrapped
    ret = await coro(*args, **kwargs)
          ^^^^^^^^^^^^^^^^^^^^^^^^^^^
  File "D:\testing\DiscordBot\main.py", line 100, in DeleteCategory
    confirm = await bot.wait_for("message", check=lambda m: m.author == message.author and m.channel == message.channel)
              ^^^^^^^^^^^^^^^^^^^^^^^^^^^^^^^^^^^^^^^^^^^^^^^^^^^^^^^^^^^^^^^^^^^^^^^^^^^^^^^^^^^^^^^^^^^^^^^^^^^^^^^^^^
  File "C:\Program Files\WindowsApps\PythonSoftwareFoundation.Python.3.13_3.13.1520.0_x64__qbz5n2kfra8p0\Lib\asyncio\tasks.py", line 507, in wait_for
    return await fut
           ^^^^^^^^^
  File "C:\Users\chike\AppData\Local\Packages\PythonSoftwareFoundation.Python.3.13_qbz5n2kfra8p0\LocalCache\local-packages\Python313\site-packages\discord\client.py", line 514, in dispatch
    result = condition(*args)
  File "D:\testing\DiscordBot\main.py", line 100, in <lambda>
    confirm = await bot.wait_for("message", check=lambda m: m.author == message.author and m.channel == message.channel)
                                                                        ^^^^^^^^^^^^^^
AttributeError: 'str' object has no attribute 'author'

The above exception was the direct cause of the following exception:

Traceback (most recent call last):
  File "C:\Users\chike\AppData\Local\Packages\PythonSoftwareFoundation.Python.3.13_qbz5n2kfra8p0\LocalCache\local-packages\Python313\site-packages\discord\ext\commands\bot.py", line 1366, in invoke
    await ctx.command.invoke(ctx)
  File "C:\Users\chike\AppData\Local\Packages\PythonSoftwareFoundation.Python.3.13_qbz5n2kfra8p0\LocalCache\local-packages\Python313\site-packages\discord\ext\commands\core.py", line 1029, in invoke
    await injected(*ctx.args, **ctx.kwargs)  # type: ignore
    ^^^^^^^^^^^^^^^^^^^^^^^^^^^^^^^^^^^^^^^
  File "C:\Users\chike\AppData\Local\Packages\PythonSoftwareFoundation.Python.3.13_qbz5n2kfra8p0\LocalCache\local-packages\Python313\site-packages\discord\ext\commands\core.py", line 244, in wrapped
    raise CommandInvokeError(exc) from exc
discord.ext.commands.errors.CommandInvokeError: Command raised an exception: AttributeError: 'str' object has no attribute 'author'
INFO:discord.client:logging in using static token
INFO:slack_bolt.AsyncApp:A new session (s_205400715043) has been established
INFO:slack_bolt.AsyncApp:Bolt app is running!
INFO:discord.gateway:Shard ID None has connected to Gateway (Session ID: b3edd99d72e0e9165362fedc83f19ec9).
ERROR:discord.ext.commands.bot:Ignoring exception in command DeleteCategory
Traceback (most recent call last):
  File "C:\Users\chike\AppData\Local\Packages\PythonSoftwareFoundation.Python.3.13_qbz5n2kfra8p0\LocalCache\local-packages\Python313\site-packages\discord\ext\commands\core.py", line 235, in wrapped
    ret = await coro(*args, **kwargs)
          ^^^^^^^^^^^^^^^^^^^^^^^^^^^
  File "D:\testing\DiscordBot\main.py", line 100, in DeleteCategory
    confirm = await bot.wait_for("message", check=lambda m: m.author == message.author and m.channel == ctx.channel)
              ^^^^^^^^^^^^^^^^^^^^^^^^^^^^^^^^^^^^^^^^^^^^^^^^^^^^^^^^^^^^^^^^^^^^^^^^^^^^^^^^^^^^^^^^^^^^^^^^^^^^^^
  File "C:\Program Files\WindowsApps\PythonSoftwareFoundation.Python.3.13_3.13.1520.0_x64__qbz5n2kfra8p0\Lib\asyncio\tasks.py", line 507, in wait_for
    return await fut
           ^^^^^^^^^
  File "C:\Users\chike\AppData\Local\Packages\PythonSoftwareFoundation.Python.3.13_qbz5n2kfra8p0\LocalCache\local-packages\Python313\site-packages\discord\client.py", line 514, in dispatch
    result = condition(*args)
  File "D:\testing\DiscordBot\main.py", line 100, in <lambda>
    confirm = await bot.wait_for("message", check=lambda m: m.author == message.author and m.channel == ctx.channel)
                                                                        ^^^^^^^^^^^^^^
AttributeError: 'str' object has no attribute 'author'

The above exception was the direct cause of the following exception:

Traceback (most recent call last):
  File "C:\Users\chike\AppData\Local\Packages\PythonSoftwareFoundation.Python.3.13_qbz5n2kfra8p0\LocalCache\local-packages\Python313\site-packages\discord\ext\commands\bot.py", line 1366, in invoke
    await ctx.command.invoke(ctx)
  File "C:\Users\chike\AppData\Local\Packages\PythonSoftwareFoundation.Python.3.13_qbz5n2kfra8p0\LocalCache\local-packages\Python313\site-packages\discord\ext\commands\core.py", line 1029, in invoke
    await injected(*ctx.args, **ctx.kwargs)  # type: ignore
    ^^^^^^^^^^^^^^^^^^^^^^^^^^^^^^^^^^^^^^^
  File "C:\Users\chike\AppData\Local\Packages\PythonSoftwareFoundation.Python.3.13_qbz5n2kfra8p0\LocalCache\local-packages\Python313\site-packages\discord\ext\commands\core.py", line 244, in wrapped
    raise CommandInvokeError(exc) from exc
discord.ext.commands.errors.CommandInvokeError: Command raised an exception: AttributeError: 'str' object has no attribute 'author'
INFO:discord.client:logging in using static token
INFO:slack_bolt.AsyncApp:A new session (s_153506361123) has been established
INFO:slack_bolt.AsyncApp:Bolt app is running!
INFO:discord.gateway:Shard ID None has connected to Gateway (Session ID: 84cc3aa413e87c7ed22e89ec3bb54516).
ERROR:discord.ext.commands.bot:Ignoring exception in command DeleteCategory
Traceback (most recent call last):
  File "C:\Users\chike\AppData\Local\Packages\PythonSoftwareFoundation.Python.3.13_qbz5n2kfra8p0\LocalCache\local-packages\Python313\site-packages\discord\ext\commands\core.py", line 235, in wrapped
    ret = await coro(*args, **kwargs)
          ^^^^^^^^^^^^^^^^^^^^^^^^^^^
  File "D:\testing\DiscordBot\main.py", line 101, in DeleteCategory
    confirm = await bot.wait_for("message", check=lambda m: m.author == message.author and m.channel == ctx.channel)
              ^^^^^^^^^^^^^^^^^^^^^^^^^^^^^^^^^^^^^^^^^^^^^^^^^^^^^^^^^^^^^^^^^^^^^^^^^^^^^^^^^^^^^^^^^^^^^^^^^^^^^^
  File "C:\Program Files\WindowsApps\PythonSoftwareFoundation.Python.3.13_3.13.1520.0_x64__qbz5n2kfra8p0\Lib\asyncio\tasks.py", line 507, in wait_for
    return await fut
           ^^^^^^^^^
  File "C:\Users\chike\AppData\Local\Packages\PythonSoftwareFoundation.Python.3.13_qbz5n2kfra8p0\LocalCache\local-packages\Python313\site-packages\discord\client.py", line 514, in dispatch
    result = condition(*args)
  File "D:\testing\DiscordBot\main.py", line 101, in <lambda>
    confirm = await bot.wait_for("message", check=lambda m: m.author == message.author and m.channel == ctx.channel)
                                                                        ^^^^^^^^^^^^^^
AttributeError: 'str' object has no attribute 'author'

The above exception was the direct cause of the following exception:

Traceback (most recent call last):
  File "C:\Users\chike\AppData\Local\Packages\PythonSoftwareFoundation.Python.3.13_qbz5n2kfra8p0\LocalCache\local-packages\Python313\site-packages\discord\ext\commands\bot.py", line 1366, in invoke
    await ctx.command.invoke(ctx)
  File "C:\Users\chike\AppData\Local\Packages\PythonSoftwareFoundation.Python.3.13_qbz5n2kfra8p0\LocalCache\local-packages\Python313\site-packages\discord\ext\commands\core.py", line 1029, in invoke
    await injected(*ctx.args, **ctx.kwargs)  # type: ignore
    ^^^^^^^^^^^^^^^^^^^^^^^^^^^^^^^^^^^^^^^
  File "C:\Users\chike\AppData\Local\Packages\PythonSoftwareFoundation.Python.3.13_qbz5n2kfra8p0\LocalCache\local-packages\Python313\site-packages\discord\ext\commands\core.py", line 244, in wrapped
    raise CommandInvokeError(exc) from exc
discord.ext.commands.errors.CommandInvokeError: Command raised an exception: AttributeError: 'str' object has no attribute 'author'
INFO:discord.client:logging in using static token
INFO:slack_bolt.AsyncApp:A new session (s_118718934819) has been established
INFO:slack_bolt.AsyncApp:Bolt app is running!
INFO:discord.gateway:Shard ID None has connected to Gateway (Session ID: ef1a1e869c75ab173be65a45f81d7179).
ERROR:discord.ext.commands.bot:Ignoring exception in command DeleteCategory
Traceback (most recent call last):
  File "C:\Users\chike\AppData\Local\Packages\PythonSoftwareFoundation.Python.3.13_qbz5n2kfra8p0\LocalCache\local-packages\Python313\site-packages\discord\ext\commands\core.py", line 235, in wrapped
    ret = await coro(*args, **kwargs)
          ^^^^^^^^^^^^^^^^^^^^^^^^^^^
  File "D:\testing\DiscordBot\main.py", line 100, in DeleteCategory
    confirm = await bot.wait_for("message", check=lambda m: m.author == message.author and m.channel == ctx.channel)
              ^^^^^^^^^^^^^^^^^^^^^^^^^^^^^^^^^^^^^^^^^^^^^^^^^^^^^^^^^^^^^^^^^^^^^^^^^^^^^^^^^^^^^^^^^^^^^^^^^^^^^^
  File "C:\Program Files\WindowsApps\PythonSoftwareFoundation.Python.3.13_3.13.1520.0_x64__qbz5n2kfra8p0\Lib\asyncio\tasks.py", line 507, in wait_for
    return await fut
           ^^^^^^^^^
  File "C:\Users\chike\AppData\Local\Packages\PythonSoftwareFoundation.Python.3.13_qbz5n2kfra8p0\LocalCache\local-packages\Python313\site-packages\discord\client.py", line 514, in dispatch
    result = condition(*args)
  File "D:\testing\DiscordBot\main.py", line 100, in <lambda>
    confirm = await bot.wait_for("message", check=lambda m: m.author == message.author and m.channel == ctx.channel)
                                                                        ^^^^^^^^^^^^^^
AttributeError: 'str' object has no attribute 'author'

The above exception was the direct cause of the following exception:

Traceback (most recent call last):
  File "C:\Users\chike\AppData\Local\Packages\PythonSoftwareFoundation.Python.3.13_qbz5n2kfra8p0\LocalCache\local-packages\Python313\site-packages\discord\ext\commands\bot.py", line 1366, in invoke
    await ctx.command.invoke(ctx)
  File "C:\Users\chike\AppData\Local\Packages\PythonSoftwareFoundation.Python.3.13_qbz5n2kfra8p0\LocalCache\local-packages\Python313\site-packages\discord\ext\commands\core.py", line 1029, in invoke
    await injected(*ctx.args, **ctx.kwargs)  # type: ignore
    ^^^^^^^^^^^^^^^^^^^^^^^^^^^^^^^^^^^^^^^
  File "C:\Users\chike\AppData\Local\Packages\PythonSoftwareFoundation.Python.3.13_qbz5n2kfra8p0\LocalCache\local-packages\Python313\site-packages\discord\ext\commands\core.py", line 244, in wrapped
    raise CommandInvokeError(exc) from exc
discord.ext.commands.errors.CommandInvokeError: Command raised an exception: AttributeError: 'str' object has no attribute 'author'
INFO:discord.client:logging in using static token
INFO:slack_bolt.AsyncApp:A new session (s_145294307107) has been established
INFO:slack_bolt.AsyncApp:Bolt app is running!
INFO:discord.gateway:Shard ID None has connected to Gateway (Session ID: fe7aa3720085e76fdffc6217a943376b).
ERROR:discord.ext.commands.bot:Ignoring exception in command DeleteCategory
Traceback (most recent call last):
  File "C:\Users\chike\AppData\Local\Packages\PythonSoftwareFoundation.Python.3.13_qbz5n2kfra8p0\LocalCache\local-packages\Python313\site-packages\discord\ext\commands\core.py", line 235, in wrapped
    ret = await coro(*args, **kwargs)
          ^^^^^^^^^^^^^^^^^^^^^^^^^^^
  File "D:\testing\DiscordBot\main.py", line 106, in DeleteCategory
    await discord.utils.get(message.guild.roles, name=f"{message} {MENTORROLE}").delete()
                            ^^^^^^^^^^^^^
AttributeError: 'str' object has no attribute 'guild'

The above exception was the direct cause of the following exception:

Traceback (most recent call last):
  File "C:\Users\chike\AppData\Local\Packages\PythonSoftwareFoundation.Python.3.13_qbz5n2kfra8p0\LocalCache\local-packages\Python313\site-packages\discord\ext\commands\bot.py", line 1366, in invoke
    await ctx.command.invoke(ctx)
  File "C:\Users\chike\AppData\Local\Packages\PythonSoftwareFoundation.Python.3.13_qbz5n2kfra8p0\LocalCache\local-packages\Python313\site-packages\discord\ext\commands\core.py", line 1029, in invoke
    await injected(*ctx.args, **ctx.kwargs)  # type: ignore
    ^^^^^^^^^^^^^^^^^^^^^^^^^^^^^^^^^^^^^^^
  File "C:\Users\chike\AppData\Local\Packages\PythonSoftwareFoundation.Python.3.13_qbz5n2kfra8p0\LocalCache\local-packages\Python313\site-packages\discord\ext\commands\core.py", line 244, in wrapped
    raise CommandInvokeError(exc) from exc
discord.ext.commands.errors.CommandInvokeError: Command raised an exception: AttributeError: 'str' object has no attribute 'guild'
INFO:discord.client:logging in using static token
INFO:slack_bolt.AsyncApp:A new session (s_154903523296) has been established
INFO:slack_bolt.AsyncApp:Bolt app is running!
INFO:discord.gateway:Shard ID None has connected to Gateway (Session ID: 70c696cf388ff88657cb69150de891f3).
ERROR:discord.ext.commands.bot:Ignoring exception in command DeleteCategory
Traceback (most recent call last):
  File "C:\Users\chike\AppData\Local\Packages\PythonSoftwareFoundation.Python.3.13_qbz5n2kfra8p0\LocalCache\local-packages\Python313\site-packages\discord\ext\commands\core.py", line 235, in wrapped
    ret = await coro(*args, **kwargs)
          ^^^^^^^^^^^^^^^^^^^^^^^^^^^
  File "D:\testing\DiscordBot\main.py", line 104, in DeleteCategory
    await discord.utils.get(message.guild.roles, name=f"{message} {MENTORROLE}").delete()
                            ^^^^^^^^^^^^^
AttributeError: 'str' object has no attribute 'guild'

The above exception was the direct cause of the following exception:

Traceback (most recent call last):
  File "C:\Users\chike\AppData\Local\Packages\PythonSoftwareFoundation.Python.3.13_qbz5n2kfra8p0\LocalCache\local-packages\Python313\site-packages\discord\ext\commands\bot.py", line 1366, in invoke
    await ctx.command.invoke(ctx)
  File "C:\Users\chike\AppData\Local\Packages\PythonSoftwareFoundation.Python.3.13_qbz5n2kfra8p0\LocalCache\local-packages\Python313\site-packages\discord\ext\commands\core.py", line 1029, in invoke
    await injected(*ctx.args, **ctx.kwargs)  # type: ignore
    ^^^^^^^^^^^^^^^^^^^^^^^^^^^^^^^^^^^^^^^
  File "C:\Users\chike\AppData\Local\Packages\PythonSoftwareFoundation.Python.3.13_qbz5n2kfra8p0\LocalCache\local-packages\Python313\site-packages\discord\ext\commands\core.py", line 244, in wrapped
    raise CommandInvokeError(exc) from exc
discord.ext.commands.errors.CommandInvokeError: Command raised an exception: AttributeError: 'str' object has no attribute 'guild'
INFO:discord.client:logging in using static token
INFO:slack_bolt.AsyncApp:A new session (s_117919067939) has been established
INFO:slack_bolt.AsyncApp:Bolt app is running!
INFO:discord.gateway:Shard ID None has connected to Gateway (Session ID: f88eae01d080dd5390e3cf8d6c3dedd6).
INFO:discord.client:logging in using static token
INFO:slack_bolt.AsyncApp:A new session (s_175936712483) has been established
INFO:slack_bolt.AsyncApp:Bolt app is running!
INFO:discord.gateway:Shard ID None has connected to Gateway (Session ID: e62ba72dbf987814186ab28cabd16e2b).
INFO:discord.client:logging in using static token
INFO:slack_bolt.AsyncApp:A new session (s_161069571875) has been established
INFO:slack_bolt.AsyncApp:Bolt app is running!
INFO:discord.gateway:Shard ID None has connected to Gateway (Session ID: f93bd387e34f3d6c4f45e9c36590cd37).
INFO:discord.client:logging in using static token
INFO:slack_bolt.AsyncApp:A new session (s_87200247587) has been established
INFO:slack_bolt.AsyncApp:Bolt app is running!
INFO:discord.gateway:Shard ID None has connected to Gateway (Session ID: 0de7917c6fdc4c1cfe4ba105be8bf94b).
INFO:discord.client:logging in using static token
INFO:slack_bolt.AsyncApp:A new session (s_105071783715) has been established
INFO:slack_bolt.AsyncApp:Bolt app is running!
INFO:discord.gateway:Shard ID None has connected to Gateway (Session ID: 0b470e3ea56b8b4613193ccb99014834).
INFO:discord.client:logging in using static token
INFO:slack_bolt.AsyncApp:A new session (s_114828365603) has been established
INFO:slack_bolt.AsyncApp:Bolt app is running!
INFO:discord.gateway:Shard ID None has connected to Gateway (Session ID: baf75877afff1bb7a04e6eb0b3e40994).
INFO:discord.client:logging in using static token
INFO:slack_bolt.AsyncApp:A new session (s_158961250083) has been established
INFO:slack_bolt.AsyncApp:Bolt app is running!
INFO:discord.gateway:Shard ID None has connected to Gateway (Session ID: 82ee1bf5d0561480b44dcbcd032f4b47).
INFO:discord.client:logging in using static token
INFO:slack_bolt.AsyncApp:A new session (s_160436863779) has been established
INFO:slack_bolt.AsyncApp:Bolt app is running!
INFO:discord.gateway:Shard ID None has connected to Gateway (Session ID: fbf070de7b4e8289b58597b2f963d894).
INFO:discord.client:logging in using static token
INFO:slack_bolt.AsyncApp:A new session (s_126715309859) has been established
INFO:slack_bolt.AsyncApp:Bolt app is running!
INFO:discord.gateway:Shard ID None has connected to Gateway (Session ID: 0db8207fccc7964632e921d68d9b1cdf).
ERROR:discord.ext.commands.bot:Ignoring exception in command RevokeRoles
Traceback (most recent call last):
  File "C:\Users\chike\AppData\Local\Packages\PythonSoftwareFoundation.Python.3.13_qbz5n2kfra8p0\LocalCache\local-packages\Python313\site-packages\discord\ext\commands\core.py", line 235, in wrapped
    ret = await coro(*args, **kwargs)
          ^^^^^^^^^^^^^^^^^^^^^^^^^^^
  File "D:\testing\DiscordBot\main.py", line 79, in RevokeRoles
    Commands.RevokeRoles(ctx, message)
    ^^^^^^^^^^^^^^^^^^^^
AttributeError: module 'Commands' has no attribute 'RevokeRoles'. Did you mean: 'RevokeRolves'?

The above exception was the direct cause of the following exception:

Traceback (most recent call last):
  File "C:\Users\chike\AppData\Local\Packages\PythonSoftwareFoundation.Python.3.13_qbz5n2kfra8p0\LocalCache\local-packages\Python313\site-packages\discord\ext\commands\bot.py", line 1366, in invoke
    await ctx.command.invoke(ctx)
  File "C:\Users\chike\AppData\Local\Packages\PythonSoftwareFoundation.Python.3.13_qbz5n2kfra8p0\LocalCache\local-packages\Python313\site-packages\discord\ext\commands\core.py", line 1029, in invoke
    await injected(*ctx.args, **ctx.kwargs)  # type: ignore
    ^^^^^^^^^^^^^^^^^^^^^^^^^^^^^^^^^^^^^^^
  File "C:\Users\chike\AppData\Local\Packages\PythonSoftwareFoundation.Python.3.13_qbz5n2kfra8p0\LocalCache\local-packages\Python313\site-packages\discord\ext\commands\core.py", line 244, in wrapped
    raise CommandInvokeError(exc) from exc
discord.ext.commands.errors.CommandInvokeError: Command raised an exception: AttributeError: module 'Commands' has no attribute 'RevokeRoles'
ERROR:discord.ext.commands.bot:Ignoring exception in command RevokeRoles
Traceback (most recent call last):
  File "C:\Users\chike\AppData\Local\Packages\PythonSoftwareFoundation.Python.3.13_qbz5n2kfra8p0\LocalCache\local-packages\Python313\site-packages\discord\ext\commands\core.py", line 235, in wrapped
    ret = await coro(*args, **kwargs)
          ^^^^^^^^^^^^^^^^^^^^^^^^^^^
  File "D:\testing\DiscordBot\main.py", line 79, in RevokeRoles
    Commands.RevokeRoles(ctx, message)
    ^^^^^^^^^^^^^^^^^^^^
AttributeError: module 'Commands' has no attribute 'RevokeRoles'. Did you mean: 'RevokeRolves'?

The above exception was the direct cause of the following exception:

Traceback (most recent call last):
  File "C:\Users\chike\AppData\Local\Packages\PythonSoftwareFoundation.Python.3.13_qbz5n2kfra8p0\LocalCache\local-packages\Python313\site-packages\discord\ext\commands\bot.py", line 1366, in invoke
    await ctx.command.invoke(ctx)
  File "C:\Users\chike\AppData\Local\Packages\PythonSoftwareFoundation.Python.3.13_qbz5n2kfra8p0\LocalCache\local-packages\Python313\site-packages\discord\ext\commands\core.py", line 1029, in invoke
    await injected(*ctx.args, **ctx.kwargs)  # type: ignore
    ^^^^^^^^^^^^^^^^^^^^^^^^^^^^^^^^^^^^^^^
  File "C:\Users\chike\AppData\Local\Packages\PythonSoftwareFoundation.Python.3.13_qbz5n2kfra8p0\LocalCache\local-packages\Python313\site-packages\discord\ext\commands\core.py", line 244, in wrapped
    raise CommandInvokeError(exc) from exc
discord.ext.commands.errors.CommandInvokeError: Command raised an exception: AttributeError: module 'Commands' has no attribute 'RevokeRoles'
INFO:discord.client:logging in using static token
INFO:slack_bolt.AsyncApp:A new session (s_145476960035) has been established
INFO:slack_bolt.AsyncApp:Bolt app is running!
INFO:discord.gateway:Shard ID None has connected to Gateway (Session ID: a06ed83dc464f51a25cc102cadc0353d).
ERROR:discord.ext.commands.bot:Ignoring exception in command RevokeRoles
Traceback (most recent call last):
  File "C:\Users\chike\AppData\Local\Packages\PythonSoftwareFoundation.Python.3.13_qbz5n2kfra8p0\LocalCache\local-packages\Python313\site-packages\discord\ext\commands\core.py", line 235, in wrapped
    ret = await coro(*args, **kwargs)
          ^^^^^^^^^^^^^^^^^^^^^^^^^^^
  File "D:\testing\DiscordBot\main.py", line 79, in RevokeRoles
    Commands.RevokeRoles(ctx, message, bot)
    ^^^^^^^^^^^^^^^^^^^^
AttributeError: module 'Commands' has no attribute 'RevokeRoles'. Did you mean: 'RevokeRolves'?

The above exception was the direct cause of the following exception:

Traceback (most recent call last):
  File "C:\Users\chike\AppData\Local\Packages\PythonSoftwareFoundation.Python.3.13_qbz5n2kfra8p0\LocalCache\local-packages\Python313\site-packages\discord\ext\commands\bot.py", line 1366, in invoke
    await ctx.command.invoke(ctx)
  File "C:\Users\chike\AppData\Local\Packages\PythonSoftwareFoundation.Python.3.13_qbz5n2kfra8p0\LocalCache\local-packages\Python313\site-packages\discord\ext\commands\core.py", line 1029, in invoke
    await injected(*ctx.args, **ctx.kwargs)  # type: ignore
    ^^^^^^^^^^^^^^^^^^^^^^^^^^^^^^^^^^^^^^^
  File "C:\Users\chike\AppData\Local\Packages\PythonSoftwareFoundation.Python.3.13_qbz5n2kfra8p0\LocalCache\local-packages\Python313\site-packages\discord\ext\commands\core.py", line 244, in wrapped
    raise CommandInvokeError(exc) from exc
discord.ext.commands.errors.CommandInvokeError: Command raised an exception: AttributeError: module 'Commands' has no attribute 'RevokeRoles'
INFO:discord.client:logging in using static token
INFO:slack_bolt.AsyncApp:A new session (s_107612011299) has been established
INFO:slack_bolt.AsyncApp:Bolt app is running!
INFO:discord.gateway:Shard ID None has connected to Gateway (Session ID: 50543f517dddea4eaf5c33e0fa008fb7).
ERROR:discord.ext.commands.bot:Ignoring exception in command RevokeRoles
Traceback (most recent call last):
  File "C:\Users\chike\AppData\Local\Packages\PythonSoftwareFoundation.Python.3.13_qbz5n2kfra8p0\LocalCache\local-packages\Python313\site-packages\discord\ext\commands\core.py", line 235, in wrapped
    ret = await coro(*args, **kwargs)
          ^^^^^^^^^^^^^^^^^^^^^^^^^^^
  File "D:\testing\DiscordBot\main.py", line 79, in RevokeRoles
    Commands.RevokeRoles(ctx, message, bot)
    ^^^^^^^^^^^^^^^^^^^^
AttributeError: module 'Commands' has no attribute 'RevokeRoles'. Did you mean: 'RevokeRolves'?

The above exception was the direct cause of the following exception:

Traceback (most recent call last):
  File "C:\Users\chike\AppData\Local\Packages\PythonSoftwareFoundation.Python.3.13_qbz5n2kfra8p0\LocalCache\local-packages\Python313\site-packages\discord\ext\commands\bot.py", line 1366, in invoke
    await ctx.command.invoke(ctx)
  File "C:\Users\chike\AppData\Local\Packages\PythonSoftwareFoundation.Python.3.13_qbz5n2kfra8p0\LocalCache\local-packages\Python313\site-packages\discord\ext\commands\core.py", line 1029, in invoke
    await injected(*ctx.args, **ctx.kwargs)  # type: ignore
    ^^^^^^^^^^^^^^^^^^^^^^^^^^^^^^^^^^^^^^^
  File "C:\Users\chike\AppData\Local\Packages\PythonSoftwareFoundation.Python.3.13_qbz5n2kfra8p0\LocalCache\local-packages\Python313\site-packages\discord\ext\commands\core.py", line 244, in wrapped
    raise CommandInvokeError(exc) from exc
discord.ext.commands.errors.CommandInvokeError: Command raised an exception: AttributeError: module 'Commands' has no attribute 'RevokeRoles'
INFO:discord.client:logging in using static token
INFO:slack_bolt.AsyncApp:A new session (s_171931479843) has been established
INFO:slack_bolt.AsyncApp:Bolt app is running!
INFO:discord.gateway:Shard ID None has connected to Gateway (Session ID: ff7511e5b666f8662a7d20d5e1bfc2a4).
ERROR:discord.ext.commands.bot:Ignoring exception in command RevokeRoles
Traceback (most recent call last):
  File "C:\Users\chike\AppData\Local\Packages\PythonSoftwareFoundation.Python.3.13_qbz5n2kfra8p0\LocalCache\local-packages\Python313\site-packages\discord\ext\commands\core.py", line 235, in wrapped
    ret = await coro(*args, **kwargs)
          ^^^^^^^^^^^^^^^^^^^^^^^^^^^
  File "D:\testing\DiscordBot\main.py", line 79, in RevokeRoles
    await Commands.RevokeRoles(ctx, message, bot)
          ^^^^^^^^^^^^^^^^^^^^
AttributeError: module 'Commands' has no attribute 'RevokeRoles'. Did you mean: 'RevokeRolves'?

The above exception was the direct cause of the following exception:

Traceback (most recent call last):
  File "C:\Users\chike\AppData\Local\Packages\PythonSoftwareFoundation.Python.3.13_qbz5n2kfra8p0\LocalCache\local-packages\Python313\site-packages\discord\ext\commands\bot.py", line 1366, in invoke
    await ctx.command.invoke(ctx)
  File "C:\Users\chike\AppData\Local\Packages\PythonSoftwareFoundation.Python.3.13_qbz5n2kfra8p0\LocalCache\local-packages\Python313\site-packages\discord\ext\commands\core.py", line 1029, in invoke
    await injected(*ctx.args, **ctx.kwargs)  # type: ignore
    ^^^^^^^^^^^^^^^^^^^^^^^^^^^^^^^^^^^^^^^
  File "C:\Users\chike\AppData\Local\Packages\PythonSoftwareFoundation.Python.3.13_qbz5n2kfra8p0\LocalCache\local-packages\Python313\site-packages\discord\ext\commands\core.py", line 244, in wrapped
    raise CommandInvokeError(exc) from exc
discord.ext.commands.errors.CommandInvokeError: Command raised an exception: AttributeError: module 'Commands' has no attribute 'RevokeRoles'
ERROR:discord.ext.commands.bot:Ignoring exception in command RevokeRoles
Traceback (most recent call last):
  File "C:\Users\chike\AppData\Local\Packages\PythonSoftwareFoundation.Python.3.13_qbz5n2kfra8p0\LocalCache\local-packages\Python313\site-packages\discord\ext\commands\core.py", line 235, in wrapped
    ret = await coro(*args, **kwargs)
          ^^^^^^^^^^^^^^^^^^^^^^^^^^^
  File "D:\testing\DiscordBot\main.py", line 79, in RevokeRoles
    await Commands.RevokeRoles(ctx, message, bot)
          ^^^^^^^^^^^^^^^^^^^^
AttributeError: module 'Commands' has no attribute 'RevokeRoles'. Did you mean: 'RevokeRolves'?

The above exception was the direct cause of the following exception:

Traceback (most recent call last):
  File "C:\Users\chike\AppData\Local\Packages\PythonSoftwareFoundation.Python.3.13_qbz5n2kfra8p0\LocalCache\local-packages\Python313\site-packages\discord\ext\commands\bot.py", line 1366, in invoke
    await ctx.command.invoke(ctx)
  File "C:\Users\chike\AppData\Local\Packages\PythonSoftwareFoundation.Python.3.13_qbz5n2kfra8p0\LocalCache\local-packages\Python313\site-packages\discord\ext\commands\core.py", line 1029, in invoke
    await injected(*ctx.args, **ctx.kwargs)  # type: ignore
    ^^^^^^^^^^^^^^^^^^^^^^^^^^^^^^^^^^^^^^^
  File "C:\Users\chike\AppData\Local\Packages\PythonSoftwareFoundation.Python.3.13_qbz5n2kfra8p0\LocalCache\local-packages\Python313\site-packages\discord\ext\commands\core.py", line 244, in wrapped
    raise CommandInvokeError(exc) from exc
discord.ext.commands.errors.CommandInvokeError: Command raised an exception: AttributeError: module 'Commands' has no attribute 'RevokeRoles'
INFO:discord.client:logging in using static token
INFO:slack_bolt.AsyncApp:A new session (s_112934656992) has been established
INFO:slack_bolt.AsyncApp:Bolt app is running!
INFO:discord.gateway:Shard ID None has connected to Gateway (Session ID: 54e4bbf808366e0fafdf6a5d05bc7b54).
ERROR:discord.ext.commands.bot:Ignoring exception in command RevokeRoles
Traceback (most recent call last):
  File "C:\Users\chike\AppData\Local\Packages\PythonSoftwareFoundation.Python.3.13_qbz5n2kfra8p0\LocalCache\local-packages\Python313\site-packages\discord\ext\commands\core.py", line 235, in wrapped
    ret = await coro(*args, **kwargs)
          ^^^^^^^^^^^^^^^^^^^^^^^^^^^
  File "D:\testing\DiscordBot\main.py", line 79, in RevokeRoles
    await Commands.RevokeRoles(ctx, message, bot)
          ^^^^^^^^^^^^^^^^^^^^
AttributeError: module 'Commands' has no attribute 'RevokeRoles'. Did you mean: 'RevokeRolves'?

The above exception was the direct cause of the following exception:

Traceback (most recent call last):
  File "C:\Users\chike\AppData\Local\Packages\PythonSoftwareFoundation.Python.3.13_qbz5n2kfra8p0\LocalCache\local-packages\Python313\site-packages\discord\ext\commands\bot.py", line 1366, in invoke
    await ctx.command.invoke(ctx)
  File "C:\Users\chike\AppData\Local\Packages\PythonSoftwareFoundation.Python.3.13_qbz5n2kfra8p0\LocalCache\local-packages\Python313\site-packages\discord\ext\commands\core.py", line 1029, in invoke
    await injected(*ctx.args, **ctx.kwargs)  # type: ignore
    ^^^^^^^^^^^^^^^^^^^^^^^^^^^^^^^^^^^^^^^
  File "C:\Users\chike\AppData\Local\Packages\PythonSoftwareFoundation.Python.3.13_qbz5n2kfra8p0\LocalCache\local-packages\Python313\site-packages\discord\ext\commands\core.py", line 244, in wrapped
    raise CommandInvokeError(exc) from exc
discord.ext.commands.errors.CommandInvokeError: Command raised an exception: AttributeError: module 'Commands' has no attribute 'RevokeRoles'
ERROR:discord.ext.commands.bot:Ignoring exception in command RevokeRoles
Traceback (most recent call last):
  File "C:\Users\chike\AppData\Local\Packages\PythonSoftwareFoundation.Python.3.13_qbz5n2kfra8p0\LocalCache\local-packages\Python313\site-packages\discord\ext\commands\core.py", line 235, in wrapped
    ret = await coro(*args, **kwargs)
          ^^^^^^^^^^^^^^^^^^^^^^^^^^^
  File "D:\testing\DiscordBot\main.py", line 79, in RevokeRoles
    await Commands.RevokeRoles(ctx, message, bot)
          ^^^^^^^^^^^^^^^^^^^^
AttributeError: module 'Commands' has no attribute 'RevokeRoles'. Did you mean: 'RevokeRolves'?

The above exception was the direct cause of the following exception:

Traceback (most recent call last):
  File "C:\Users\chike\AppData\Local\Packages\PythonSoftwareFoundation.Python.3.13_qbz5n2kfra8p0\LocalCache\local-packages\Python313\site-packages\discord\ext\commands\bot.py", line 1366, in invoke
    await ctx.command.invoke(ctx)
  File "C:\Users\chike\AppData\Local\Packages\PythonSoftwareFoundation.Python.3.13_qbz5n2kfra8p0\LocalCache\local-packages\Python313\site-packages\discord\ext\commands\core.py", line 1029, in invoke
    await injected(*ctx.args, **ctx.kwargs)  # type: ignore
    ^^^^^^^^^^^^^^^^^^^^^^^^^^^^^^^^^^^^^^^
  File "C:\Users\chike\AppData\Local\Packages\PythonSoftwareFoundation.Python.3.13_qbz5n2kfra8p0\LocalCache\local-packages\Python313\site-packages\discord\ext\commands\core.py", line 244, in wrapped
    raise CommandInvokeError(exc) from exc
discord.ext.commands.errors.CommandInvokeError: Command raised an exception: AttributeError: module 'Commands' has no attribute 'RevokeRoles'
ERROR:discord.ext.commands.bot:Ignoring exception in command RevokeRoles
Traceback (most recent call last):
  File "C:\Users\chike\AppData\Local\Packages\PythonSoftwareFoundation.Python.3.13_qbz5n2kfra8p0\LocalCache\local-packages\Python313\site-packages\discord\ext\commands\core.py", line 235, in wrapped
    ret = await coro(*args, **kwargs)
          ^^^^^^^^^^^^^^^^^^^^^^^^^^^
  File "D:\testing\DiscordBot\main.py", line 79, in RevokeRoles
    await Commands.RevokeRoles(ctx, message, bot)
          ^^^^^^^^^^^^^^^^^^^^
AttributeError: module 'Commands' has no attribute 'RevokeRoles'. Did you mean: 'RevokeRolves'?

The above exception was the direct cause of the following exception:

Traceback (most recent call last):
  File "C:\Users\chike\AppData\Local\Packages\PythonSoftwareFoundation.Python.3.13_qbz5n2kfra8p0\LocalCache\local-packages\Python313\site-packages\discord\ext\commands\bot.py", line 1366, in invoke
    await ctx.command.invoke(ctx)
  File "C:\Users\chike\AppData\Local\Packages\PythonSoftwareFoundation.Python.3.13_qbz5n2kfra8p0\LocalCache\local-packages\Python313\site-packages\discord\ext\commands\core.py", line 1029, in invoke
    await injected(*ctx.args, **ctx.kwargs)  # type: ignore
    ^^^^^^^^^^^^^^^^^^^^^^^^^^^^^^^^^^^^^^^
  File "C:\Users\chike\AppData\Local\Packages\PythonSoftwareFoundation.Python.3.13_qbz5n2kfra8p0\LocalCache\local-packages\Python313\site-packages\discord\ext\commands\core.py", line 244, in wrapped
    raise CommandInvokeError(exc) from exc
discord.ext.commands.errors.CommandInvokeError: Command raised an exception: AttributeError: module 'Commands' has no attribute 'RevokeRoles'
ERROR:discord.ext.commands.bot:Ignoring exception in command RevokeRoles
Traceback (most recent call last):
  File "C:\Users\chike\AppData\Local\Packages\PythonSoftwareFoundation.Python.3.13_qbz5n2kfra8p0\LocalCache\local-packages\Python313\site-packages\discord\ext\commands\core.py", line 235, in wrapped
    ret = await coro(*args, **kwargs)
          ^^^^^^^^^^^^^^^^^^^^^^^^^^^
  File "D:\testing\DiscordBot\main.py", line 79, in RevokeRoles
    await Commands.RevokeRoles(ctx, message, bot)
          ^^^^^^^^^^^^^^^^^^^^
AttributeError: module 'Commands' has no attribute 'RevokeRoles'. Did you mean: 'RevokeRolves'?

The above exception was the direct cause of the following exception:

Traceback (most recent call last):
  File "C:\Users\chike\AppData\Local\Packages\PythonSoftwareFoundation.Python.3.13_qbz5n2kfra8p0\LocalCache\local-packages\Python313\site-packages\discord\ext\commands\bot.py", line 1366, in invoke
    await ctx.command.invoke(ctx)
  File "C:\Users\chike\AppData\Local\Packages\PythonSoftwareFoundation.Python.3.13_qbz5n2kfra8p0\LocalCache\local-packages\Python313\site-packages\discord\ext\commands\core.py", line 1029, in invoke
    await injected(*ctx.args, **ctx.kwargs)  # type: ignore
    ^^^^^^^^^^^^^^^^^^^^^^^^^^^^^^^^^^^^^^^
  File "C:\Users\chike\AppData\Local\Packages\PythonSoftwareFoundation.Python.3.13_qbz5n2kfra8p0\LocalCache\local-packages\Python313\site-packages\discord\ext\commands\core.py", line 244, in wrapped
    raise CommandInvokeError(exc) from exc
discord.ext.commands.errors.CommandInvokeError: Command raised an exception: AttributeError: module 'Commands' has no attribute 'RevokeRoles'
WARNING:discord.http:We are being rate limited. DELETE https://discord.com/api/v10/channels/1377739818234282167/messages/1395529790630400090 responded with 429. Retrying in 0.57 seconds.
WARNING:discord.http:We are being rate limited. DELETE https://discord.com/api/v10/channels/1377739818234282167/messages/1395529718186512475 responded with 429. Retrying in 0.69 seconds.
WARNING:discord.http:We are being rate limited. DELETE https://discord.com/api/v10/channels/1377739818234282167/messages/1395529716491882648 responded with 429. Retrying in 0.61 seconds.
WARNING:discord.http:We are being rate limited. DELETE https://discord.com/api/v10/channels/1377739818234282167/messages/1395529715942690997 responded with 429. Retrying in 0.64 seconds.
WARNING:discord.http:We are being rate limited. DELETE https://discord.com/api/v10/channels/1377739818234282167/messages/1395529703003127910 responded with 429. Retrying in 0.30 seconds.
WARNING:discord.http:We are being rate limited. DELETE https://discord.com/api/v10/channels/1377739818234282167/messages/1395529701984047105 responded with 429. Retrying in 0.70 seconds.
WARNING:discord.http:We are being rate limited. DELETE https://discord.com/api/v10/channels/1377739818234282167/messages/1395529700427694251 responded with 429. Retrying in 0.57 seconds.
WARNING:discord.http:We are being rate limited. DELETE https://discord.com/api/v10/channels/1377739818234282167/messages/1395529692232159403 responded with 429. Retrying in 0.75 seconds.
WARNING:discord.http:We are being rate limited. DELETE https://discord.com/api/v10/channels/1377739818234282167/messages/1395529691305213982 responded with 429. Retrying in 0.59 seconds.
WARNING:discord.http:We are being rate limited. DELETE https://discord.com/api/v10/channels/1377739818234282167/messages/1395529690503970969 responded with 429. Retrying in 0.72 seconds.
WARNING:discord.http:We are being rate limited. DELETE https://discord.com/api/v10/channels/1377739818234282167/messages/1395529684690800731 responded with 429. Retrying in 0.74 seconds.
WARNING:discord.http:We are being rate limited. DELETE https://discord.com/api/v10/channels/1377739818234282167/messages/1395529683981959249 responded with 429. Retrying in 0.66 seconds.
WARNING:discord.http:We are being rate limited. DELETE https://discord.com/api/v10/channels/1377739818234282167/messages/1395529513391095860 responded with 429. Retrying in 0.68 seconds.
WARNING:discord.http:We are being rate limited. DELETE https://discord.com/api/v10/channels/1377739818234282167/messages/1395529512720011288 responded with 429. Retrying in 0.72 seconds.
WARNING:discord.http:We are being rate limited. DELETE https://discord.com/api/v10/channels/1377739818234282167/messages/1395529502448287928 responded with 429. Retrying in 0.74 seconds.
WARNING:discord.http:We are being rate limited. DELETE https://discord.com/api/v10/channels/1377739818234282167/messages/1395529501718478870 responded with 429. Retrying in 0.76 seconds.
WARNING:discord.http:We are being rate limited. DELETE https://discord.com/api/v10/channels/1377739818234282167/messages/1395529416829829302 responded with 429. Retrying in 0.75 seconds.
WARNING:discord.http:We are being rate limited. DELETE https://discord.com/api/v10/channels/1377739818234282167/messages/1395529416192299174 responded with 429. Retrying in 0.71 seconds.
WARNING:discord.http:We are being rate limited. DELETE https://discord.com/api/v10/channels/1377739818234282167/messages/1395529401692717238 responded with 429. Retrying in 0.72 seconds.
WARNING:discord.http:We are being rate limited. DELETE https://discord.com/api/v10/channels/1377739818234282167/messages/1395529401088872548 responded with 429. Retrying in 0.64 seconds.
WARNING:discord.http:We are being rate limited. DELETE https://discord.com/api/v10/channels/1377739818234282167/messages/1395529175686709269 responded with 429. Retrying in 0.66 seconds.
ERROR:discord.ext.commands.bot:Ignoring exception in command None
discord.ext.commands.errors.CommandNotFound: Command "clear" is not found
ERROR:discord.ext.commands.bot:Ignoring exception in command Clear
Traceback (most recent call last):
  File "C:\Users\chike\AppData\Local\Packages\PythonSoftwareFoundation.Python.3.13_qbz5n2kfra8p0\LocalCache\local-packages\Python313\site-packages\discord\ext\commands\bot.py", line 1366, in invoke
    await ctx.command.invoke(ctx)
  File "C:\Users\chike\AppData\Local\Packages\PythonSoftwareFoundation.Python.3.13_qbz5n2kfra8p0\LocalCache\local-packages\Python313\site-packages\discord\ext\commands\core.py", line 1021, in invoke
    await self.prepare(ctx)
  File "C:\Users\chike\AppData\Local\Packages\PythonSoftwareFoundation.Python.3.13_qbz5n2kfra8p0\LocalCache\local-packages\Python313\site-packages\discord\ext\commands\core.py", line 938, in prepare
    await self._parse_arguments(ctx)
  File "C:\Users\chike\AppData\Local\Packages\PythonSoftwareFoundation.Python.3.13_qbz5n2kfra8p0\LocalCache\local-packages\Python313\site-packages\discord\ext\commands\core.py", line 845, in _parse_arguments
    transformed = await self.transform(ctx, param, attachments)
                  ^^^^^^^^^^^^^^^^^^^^^^^^^^^^^^^^^^^^^^^^^^^^^
  File "C:\Users\chike\AppData\Local\Packages\PythonSoftwareFoundation.Python.3.13_qbz5n2kfra8p0\LocalCache\local-packages\Python313\site-packages\discord\ext\commands\core.py", line 697, in transform
    raise MissingRequiredArgument(param)
discord.ext.commands.errors.MissingRequiredArgument: amount is a required argument that is missing.
WARNING:discord.http:We are being rate limited. DELETE https://discord.com/api/v10/channels/1377739818234282167/messages/1395529139431411822 responded with 429. Retrying in 0.30 seconds.
WARNING:discord.http:We are being rate limited. DELETE https://discord.com/api/v10/channels/1377739818234282167/messages/1395529138038771796 responded with 429. Retrying in 0.43 seconds.
WARNING:discord.http:We are being rate limited. DELETE https://discord.com/api/v10/channels/1377739818234282167/messages/1395529136952443001 responded with 429. Retrying in 0.73 seconds.
WARNING:discord.http:We are being rate limited. DELETE https://discord.com/api/v10/channels/1377739818234282167/messages/1395529130011005042 responded with 429. Retrying in 0.68 seconds.
WARNING:discord.http:We are being rate limited. DELETE https://discord.com/api/v10/channels/1377739818234282167/messages/1395529129343848581 responded with 429. Retrying in 0.75 seconds.
WARNING:discord.http:We are being rate limited. DELETE https://discord.com/api/v10/channels/1377739818234282167/messages/1395529004873814272 responded with 429. Retrying in 0.64 seconds.
WARNING:discord.http:We are being rate limited. DELETE https://discord.com/api/v10/channels/1377739818234282167/messages/1395529004135743540 responded with 429. Retrying in 0.74 seconds.
WARNING:discord.http:We are being rate limited. DELETE https://discord.com/api/v10/channels/1377739818234282167/messages/1395529003749736499 responded with 429. Retrying in 0.65 seconds.
WARNING:discord.http:We are being rate limited. DELETE https://discord.com/api/v10/channels/1377739818234282167/messages/1395528994111357078 responded with 429. Retrying in 0.65 seconds.
WARNING:discord.http:We are being rate limited. DELETE https://discord.com/api/v10/channels/1377739818234282167/messages/1395528993280888943 responded with 429. Retrying in 0.72 seconds.
ERROR:discord.ext.commands.bot:Ignoring exception in command None
discord.ext.commands.errors.CommandNotFound: Command "Create" is not found
INFO:discord.client:logging in using static token
INFO:slack_bolt.AsyncApp:A new session (s_90937438176) has been established
INFO:slack_bolt.AsyncApp:Bolt app is running!
INFO:discord.gateway:Shard ID None has connected to Gateway (Session ID: 079988a93d48f25fb09f1bc5caf3def9).
INFO:discord.client:logging in using static token
INFO:slack_bolt.AsyncApp:A new session (s_188686809870) has been established
INFO:slack_bolt.AsyncApp:Bolt app is running!
INFO:discord.gateway:Shard ID None has connected to Gateway (Session ID: 8a0c7a929287975b3883cf36b82061d8).
INFO:discord.client:logging in using static token
INFO:slack_bolt.AsyncApp:A new session (s_162887588643) has been established
INFO:slack_bolt.AsyncApp:Bolt app is running!
INFO:discord.gateway:Shard ID None has connected to Gateway (Session ID: baaee7cc505cf97a484a1f9c6cf6016d).
INFO:discord.client:logging in using static token
INFO:slack_bolt.AsyncApp:A new session (s_149209299936) has been established
INFO:slack_bolt.AsyncApp:Bolt app is running!
INFO:discord.gateway:Shard ID None has connected to Gateway (Session ID: 7ec27aa2aeced3f9d080326a7ff0a015).
INFO:discord.client:logging in using static token
INFO:slack_bolt.AsyncApp:A new session (s_145906291596) has been established
INFO:slack_bolt.AsyncApp:Bolt app is running!
INFO:discord.gateway:Shard ID None has connected to Gateway (Session ID: 41256138fa813c2d23aef7ba0755d627).
ERROR:discord.ext.commands.bot:Ignoring exception in command DeleteCategory
Traceback (most recent call last):
  File "C:\Users\Gavin Liles\AppData\Local\Programs\Python\Python313\Lib\site-packages\discord\ext\commands\core.py", line 235, in wrapped
    ret = await coro(*args, **kwargs)
          ^^^^^^^^^^^^^^^^^^^^^^^^^^^
  File "C:\Users\Gavin Liles\Documents\codeproject\DiscordBot\DiscordBot\main.py", line 74, in DeleteCategory
    await Commands.DeleteCategory(ctx, message, bot, MENTORROLE)
  File "C:\Users\Gavin Liles\Documents\codeproject\DiscordBot\DiscordBot\Commands.py", line 103, in DeleteCategory
    filepath = category + ".toml"
               ~~~~~~~~~^~~~~~~~~
TypeError: unsupported operand type(s) for +: 'CategoryChannel' and 'str'

The above exception was the direct cause of the following exception:

Traceback (most recent call last):
  File "C:\Users\Gavin Liles\AppData\Local\Programs\Python\Python313\Lib\site-packages\discord\ext\commands\bot.py", line 1366, in invoke
    await ctx.command.invoke(ctx)
  File "C:\Users\Gavin Liles\AppData\Local\Programs\Python\Python313\Lib\site-packages\discord\ext\commands\core.py", line 1029, in invoke
    await injected(*ctx.args, **ctx.kwargs)  # type: ignore
    ^^^^^^^^^^^^^^^^^^^^^^^^^^^^^^^^^^^^^^^
  File "C:\Users\Gavin Liles\AppData\Local\Programs\Python\Python313\Lib\site-packages\discord\ext\commands\core.py", line 244, in wrapped
    raise CommandInvokeError(exc) from exc
discord.ext.commands.errors.CommandInvokeError: Command raised an exception: TypeError: unsupported operand type(s) for +: 'CategoryChannel' and 'str'
INFO:slack_bolt.AsyncApp:The session (s_145906291596) seems to be already closed. Reconnecting...
INFO:slack_bolt.AsyncApp:The old session (s_145906291596) has been abandoned
INFO:slack_bolt.AsyncApp:A new session (s_145906272381) has been established
INFO:discord.client:logging in using static token
INFO:slack_bolt.AsyncApp:A new session (s_166547116940) has been established
INFO:slack_bolt.AsyncApp:Bolt app is running!
INFO:discord.gateway:Shard ID None has connected to Gateway (Session ID: 869ad7084523368e9549e59f697dbfee).
ERROR:discord.ext.commands.bot:Ignoring exception in command DeleteCategory
Traceback (most recent call last):
  File "C:\Users\Gavin Liles\AppData\Local\Programs\Python\Python313\Lib\site-packages\discord\ext\commands\core.py", line 235, in wrapped
    ret = await coro(*args, **kwargs)
          ^^^^^^^^^^^^^^^^^^^^^^^^^^^
  File "C:\Users\Gavin Liles\Documents\codeproject\DiscordBot\DiscordBot\main.py", line 74, in DeleteCategory
    await Commands.DeleteCategory(ctx, message, bot, MENTORROLE)
  File "C:\Users\Gavin Liles\Documents\codeproject\DiscordBot\DiscordBot\Commands.py", line 103, in DeleteCategory
    filepath = category + "_tokens.toml"
               ~~~~~~~~~^~~~~~~~~~~~~~~~
TypeError: unsupported operand type(s) for +: 'CategoryChannel' and 'str'

The above exception was the direct cause of the following exception:

Traceback (most recent call last):
  File "C:\Users\Gavin Liles\AppData\Local\Programs\Python\Python313\Lib\site-packages\discord\ext\commands\bot.py", line 1366, in invoke
    await ctx.command.invoke(ctx)
  File "C:\Users\Gavin Liles\AppData\Local\Programs\Python\Python313\Lib\site-packages\discord\ext\commands\core.py", line 1029, in invoke
    await injected(*ctx.args, **ctx.kwargs)  # type: ignore
    ^^^^^^^^^^^^^^^^^^^^^^^^^^^^^^^^^^^^^^^
  File "C:\Users\Gavin Liles\AppData\Local\Programs\Python\Python313\Lib\site-packages\discord\ext\commands\core.py", line 244, in wrapped
    raise CommandInvokeError(exc) from exc
discord.ext.commands.errors.CommandInvokeError: Command raised an exception: TypeError: unsupported operand type(s) for +: 'CategoryChannel' and 'str'
INFO:discord.client:logging in using static token
INFO:slack_bolt.AsyncApp:A new session (s_110884102007) has been established
INFO:slack_bolt.AsyncApp:Bolt app is running!
INFO:discord.gateway:Shard ID None has connected to Gateway (Session ID: 5e6922e8cdea24bd46bfccc0b3f0e7b0).
INFO:discord.client:logging in using static token
INFO:slack_bolt.AsyncApp:A new session (s_108655064951) has been established
INFO:slack_bolt.AsyncApp:Bolt app is running!
INFO:discord.gateway:Shard ID None has connected to Gateway (Session ID: 903dba0130e22701620e194e71a5b662).
INFO:discord.client:logging in using static token
INFO:slack_bolt.AsyncApp:A new session (s_127558492023) has been established
INFO:slack_bolt.AsyncApp:Bolt app is running!
INFO:discord.gateway:Shard ID None has connected to Gateway (Session ID: c188cf99adeca13ac92430dbeaec444c).
ERROR:discord.ext.commands.bot:Ignoring exception in command DeleteCategory
Traceback (most recent call last):
  File "C:\Users\Gavin Liles\AppData\Local\Programs\Python\Python313\Lib\site-packages\discord\ext\commands\core.py", line 235, in wrapped
    ret = await coro(*args, **kwargs)
          ^^^^^^^^^^^^^^^^^^^^^^^^^^^
  File "C:\Users\Gavin Liles\Documents\codeproject\DiscordBot\DiscordBot\main.py", line 74, in DeleteCategory
    await Commands.DeleteCategory(ctx, message, bot, MENTORROLE)
  File "C:\Users\Gavin Liles\Documents\codeproject\DiscordBot\DiscordBot\Commands.py", line 107, in DeleteCategory
    filename = f"{category.replace(' ', '_').lower()}_tokens.toml"
                  ^^^^^^^^^^^^^^^^
AttributeError: 'CategoryChannel' object has no attribute 'replace'

The above exception was the direct cause of the following exception:

Traceback (most recent call last):
  File "C:\Users\Gavin Liles\AppData\Local\Programs\Python\Python313\Lib\site-packages\discord\ext\commands\bot.py", line 1366, in invoke
    await ctx.command.invoke(ctx)
  File "C:\Users\Gavin Liles\AppData\Local\Programs\Python\Python313\Lib\site-packages\discord\ext\commands\core.py", line 1029, in invoke
    await injected(*ctx.args, **ctx.kwargs)  # type: ignore
    ^^^^^^^^^^^^^^^^^^^^^^^^^^^^^^^^^^^^^^^
  File "C:\Users\Gavin Liles\AppData\Local\Programs\Python\Python313\Lib\site-packages\discord\ext\commands\core.py", line 244, in wrapped
    raise CommandInvokeError(exc) from exc
discord.ext.commands.errors.CommandInvokeError: Command raised an exception: AttributeError: 'CategoryChannel' object has no attribute 'replace'
INFO:discord.client:logging in using static token
INFO:slack_bolt.AsyncApp:A new session (s_152249343863) has been established
INFO:slack_bolt.AsyncApp:Bolt app is running!
INFO:discord.gateway:Shard ID None has connected to Gateway (Session ID: 9c24e25646dc58ae42a057d86365ba8e).
INFO:discord.gateway:Shard ID None has successfully RESUMED session 9c24e25646dc58ae42a057d86365ba8e.
INFO:discord.gateway:Shard ID None has successfully RESUMED session 9c24e25646dc58ae42a057d86365ba8e.
INFO:slack_bolt.AsyncApp:The old session (s_152249343863) has been abandoned
INFO:slack_bolt.AsyncApp:A new session (s_152249326493) has been established
INFO:discord.gateway:Shard ID None has successfully RESUMED session 9c24e25646dc58ae42a057d86365ba8e.
INFO:discord.gateway:Shard ID None has successfully RESUMED session 9c24e25646dc58ae42a057d86365ba8e.
INFO:slack_bolt.AsyncApp:The old session (s_152249326493) has been abandoned
INFO:slack_bolt.AsyncApp:A new session (s_152249326053) has been established
INFO:discord.client:logging in using static token
INFO:slack_bolt.AsyncApp:A new session (s_123183192972) has been established
INFO:slack_bolt.AsyncApp:Bolt app is running!
INFO:discord.gateway:Shard ID None has connected to Gateway (Session ID: a206fc7ed209cef568bc69cd5a7bf5ae).
ERROR:discord.ext.commands.bot:Ignoring exception in command DeleteCategory
Traceback (most recent call last):
  File "C:\Users\Gavin Liles\AppData\Local\Programs\Python\Python313\Lib\site-packages\discord\ext\commands\core.py", line 235, in wrapped
    ret = await coro(*args, **kwargs)
          ^^^^^^^^^^^^^^^^^^^^^^^^^^^
  File "C:\Users\Gavin Liles\Documents\codeproject\DiscordBot\DiscordBot\main.py", line 74, in DeleteCategory
    await Commands.DeleteCategory(ctx, message, bot, MENTORROLE)
  File "C:\Users\Gavin Liles\Documents\codeproject\DiscordBot\DiscordBot\Commands.py", line 96, in DeleteCategory
    await category.delete()
    ^^^^^^^^^^^^^^^^^
  File "C:\Users\Gavin Liles\AppData\Local\Programs\Python\Python313\Lib\site-packages\discord\abc.py", line 871, in delete
    await self._state.http.delete_channel(self.id, reason=reason)
  File "C:\Users\Gavin Liles\AppData\Local\Programs\Python\Python313\Lib\site-packages\discord\http.py", line 758, in request
    raise NotFound(response, data)
discord.errors.NotFound: 404 Not Found (error code: 10003): Unknown Channel

The above exception was the direct cause of the following exception:

Traceback (most recent call last):
  File "C:\Users\Gavin Liles\AppData\Local\Programs\Python\Python313\Lib\site-packages\discord\ext\commands\bot.py", line 1366, in invoke
    await ctx.command.invoke(ctx)
  File "C:\Users\Gavin Liles\AppData\Local\Programs\Python\Python313\Lib\site-packages\discord\ext\commands\core.py", line 1029, in invoke
    await injected(*ctx.args, **ctx.kwargs)  # type: ignore
    ^^^^^^^^^^^^^^^^^^^^^^^^^^^^^^^^^^^^^^^
  File "C:\Users\Gavin Liles\AppData\Local\Programs\Python\Python313\Lib\site-packages\discord\ext\commands\core.py", line 244, in wrapped
    raise CommandInvokeError(exc) from exc
discord.ext.commands.errors.CommandInvokeError: Command raised an exception: NotFound: 404 Not Found (error code: 10003): Unknown Channel
ERROR:discord.ext.commands.bot:Ignoring exception in command DeleteCategory
Traceback (most recent call last):
  File "C:\Users\Gavin Liles\AppData\Local\Programs\Python\Python313\Lib\site-packages\discord\ext\commands\core.py", line 235, in wrapped
    ret = await coro(*args, **kwargs)
          ^^^^^^^^^^^^^^^^^^^^^^^^^^^
  File "C:\Users\Gavin Liles\Documents\codeproject\DiscordBot\DiscordBot\main.py", line 74, in DeleteCategory
    await Commands.DeleteCategory(ctx, message, bot, MENTORROLE)
  File "C:\Users\Gavin Liles\Documents\codeproject\DiscordBot\DiscordBot\Commands.py", line 96, in DeleteCategory
    await category.delete()
    ^^^^^^^^^^^^^^^^^
  File "C:\Users\Gavin Liles\AppData\Local\Programs\Python\Python313\Lib\site-packages\discord\abc.py", line 871, in delete
    await self._state.http.delete_channel(self.id, reason=reason)
  File "C:\Users\Gavin Liles\AppData\Local\Programs\Python\Python313\Lib\site-packages\discord\http.py", line 758, in request
    raise NotFound(response, data)
discord.errors.NotFound: 404 Not Found (error code: 10003): Unknown Channel

The above exception was the direct cause of the following exception:

Traceback (most recent call last):
  File "C:\Users\Gavin Liles\AppData\Local\Programs\Python\Python313\Lib\site-packages\discord\ext\commands\bot.py", line 1366, in invoke
    await ctx.command.invoke(ctx)
  File "C:\Users\Gavin Liles\AppData\Local\Programs\Python\Python313\Lib\site-packages\discord\ext\commands\core.py", line 1029, in invoke
    await injected(*ctx.args, **ctx.kwargs)  # type: ignore
    ^^^^^^^^^^^^^^^^^^^^^^^^^^^^^^^^^^^^^^^
  File "C:\Users\Gavin Liles\AppData\Local\Programs\Python\Python313\Lib\site-packages\discord\ext\commands\core.py", line 244, in wrapped
    raise CommandInvokeError(exc) from exc
discord.ext.commands.errors.CommandInvokeError: Command raised an exception: NotFound: 404 Not Found (error code: 10003): Unknown Channel
INFO:discord.client:logging in using static token
INFO:slack_bolt.AsyncApp:A new session (s_170748881804) has been established
INFO:slack_bolt.AsyncApp:Bolt app is running!
INFO:discord.gateway:Shard ID None has connected to Gateway (Session ID: a39cb780eccec08104598374d972e699).
ERROR:discord.ext.commands.bot:Ignoring exception in command DeleteCategory
Traceback (most recent call last):
  File "C:\Users\Gavin Liles\AppData\Local\Programs\Python\Python313\Lib\site-packages\discord\ext\commands\core.py", line 235, in wrapped
    ret = await coro(*args, **kwargs)
          ^^^^^^^^^^^^^^^^^^^^^^^^^^^
  File "C:\Users\Gavin Liles\Documents\codeproject\DiscordBot\DiscordBot\main.py", line 74, in DeleteCategory
    await Commands.DeleteCategory(ctx, message, bot, MENTORROLE)
  File "C:\Users\Gavin Liles\Documents\codeproject\DiscordBot\DiscordBot\Commands.py", line 94, in DeleteCategory
    await ch.delete()
  File "C:\Users\Gavin Liles\AppData\Local\Programs\Python\Python313\Lib\site-packages\discord\abc.py", line 871, in delete
    await self._state.http.delete_channel(self.id, reason=reason)
  File "C:\Users\Gavin Liles\AppData\Local\Programs\Python\Python313\Lib\site-packages\discord\http.py", line 758, in request
    raise NotFound(response, data)
discord.errors.NotFound: 404 Not Found (error code: 10003): Unknown Channel

The above exception was the direct cause of the following exception:

Traceback (most recent call last):
  File "C:\Users\Gavin Liles\AppData\Local\Programs\Python\Python313\Lib\site-packages\discord\ext\commands\bot.py", line 1366, in invoke
    await ctx.command.invoke(ctx)
  File "C:\Users\Gavin Liles\AppData\Local\Programs\Python\Python313\Lib\site-packages\discord\ext\commands\core.py", line 1029, in invoke
    await injected(*ctx.args, **ctx.kwargs)  # type: ignore
    ^^^^^^^^^^^^^^^^^^^^^^^^^^^^^^^^^^^^^^^
  File "C:\Users\Gavin Liles\AppData\Local\Programs\Python\Python313\Lib\site-packages\discord\ext\commands\core.py", line 244, in wrapped
    raise CommandInvokeError(exc) from exc
discord.ext.commands.errors.CommandInvokeError: Command raised an exception: NotFound: 404 Not Found (error code: 10003): Unknown Channel
ERROR:discord.ext.commands.bot:Ignoring exception in command DeleteCategory
Traceback (most recent call last):
  File "C:\Users\Gavin Liles\AppData\Local\Programs\Python\Python313\Lib\site-packages\discord\ext\commands\core.py", line 235, in wrapped
    ret = await coro(*args, **kwargs)
          ^^^^^^^^^^^^^^^^^^^^^^^^^^^
  File "C:\Users\Gavin Liles\Documents\codeproject\DiscordBot\DiscordBot\main.py", line 74, in DeleteCategory
    await Commands.DeleteCategory(ctx, message, bot, MENTORROLE)
  File "C:\Users\Gavin Liles\Documents\codeproject\DiscordBot\DiscordBot\Commands.py", line 94, in DeleteCategory
    await ch.delete()
  File "C:\Users\Gavin Liles\AppData\Local\Programs\Python\Python313\Lib\site-packages\discord\abc.py", line 871, in delete
    await self._state.http.delete_channel(self.id, reason=reason)
  File "C:\Users\Gavin Liles\AppData\Local\Programs\Python\Python313\Lib\site-packages\discord\http.py", line 758, in request
    raise NotFound(response, data)
discord.errors.NotFound: 404 Not Found (error code: 10003): Unknown Channel

The above exception was the direct cause of the following exception:

Traceback (most recent call last):
  File "C:\Users\Gavin Liles\AppData\Local\Programs\Python\Python313\Lib\site-packages\discord\ext\commands\bot.py", line 1366, in invoke
    await ctx.command.invoke(ctx)
  File "C:\Users\Gavin Liles\AppData\Local\Programs\Python\Python313\Lib\site-packages\discord\ext\commands\core.py", line 1029, in invoke
    await injected(*ctx.args, **ctx.kwargs)  # type: ignore
    ^^^^^^^^^^^^^^^^^^^^^^^^^^^^^^^^^^^^^^^
  File "C:\Users\Gavin Liles\AppData\Local\Programs\Python\Python313\Lib\site-packages\discord\ext\commands\core.py", line 244, in wrapped
    raise CommandInvokeError(exc) from exc
discord.ext.commands.errors.CommandInvokeError: Command raised an exception: NotFound: 404 Not Found (error code: 10003): Unknown Channel
INFO:discord.client:logging in using static token
INFO:slack_bolt.AsyncApp:A new session (s_125268810636) has been established
INFO:slack_bolt.AsyncApp:Bolt app is running!
INFO:discord.gateway:Shard ID None has connected to Gateway (Session ID: ad253873048831d3c3621cd9843829b2).
ERROR:discord.ext.commands.bot:Ignoring exception in command DeleteCategory
Traceback (most recent call last):
  File "C:\Users\Gavin Liles\AppData\Local\Programs\Python\Python313\Lib\site-packages\discord\ext\commands\core.py", line 235, in wrapped
    ret = await coro(*args, **kwargs)
          ^^^^^^^^^^^^^^^^^^^^^^^^^^^
  File "C:\Users\Gavin Liles\Documents\codeproject\DiscordBot\DiscordBot\main.py", line 74, in DeleteCategory
    await Commands.DeleteCategory(ctx, message, bot, MENTORROLE)
  File "C:\Users\Gavin Liles\Documents\codeproject\DiscordBot\DiscordBot\Commands.py", line 96, in DeleteCategory
    await category.delete()
    ^^^^^^^^^^^^^^^^^
  File "C:\Users\Gavin Liles\AppData\Local\Programs\Python\Python313\Lib\site-packages\discord\abc.py", line 871, in delete
    await self._state.http.delete_channel(self.id, reason=reason)
  File "C:\Users\Gavin Liles\AppData\Local\Programs\Python\Python313\Lib\site-packages\discord\http.py", line 758, in request
    raise NotFound(response, data)
discord.errors.NotFound: 404 Not Found (error code: 10003): Unknown Channel

The above exception was the direct cause of the following exception:

Traceback (most recent call last):
  File "C:\Users\Gavin Liles\AppData\Local\Programs\Python\Python313\Lib\site-packages\discord\ext\commands\bot.py", line 1366, in invoke
    await ctx.command.invoke(ctx)
  File "C:\Users\Gavin Liles\AppData\Local\Programs\Python\Python313\Lib\site-packages\discord\ext\commands\core.py", line 1029, in invoke
    await injected(*ctx.args, **ctx.kwargs)  # type: ignore
    ^^^^^^^^^^^^^^^^^^^^^^^^^^^^^^^^^^^^^^^
  File "C:\Users\Gavin Liles\AppData\Local\Programs\Python\Python313\Lib\site-packages\discord\ext\commands\core.py", line 244, in wrapped
    raise CommandInvokeError(exc) from exc
discord.ext.commands.errors.CommandInvokeError: Command raised an exception: NotFound: 404 Not Found (error code: 10003): Unknown Channel
INFO:discord.client:logging in using static token
INFO:slack_bolt.AsyncApp:A new session (s_114566909815) has been established
INFO:slack_bolt.AsyncApp:Bolt app is running!
INFO:discord.gateway:Shard ID None has connected to Gateway (Session ID: 93b3ca5b0ccf9f660637a50f3e235d7c).
INFO:discord.client:logging in using static token
INFO:slack_bolt.AsyncApp:A new session (s_100656652151) has been established
INFO:slack_bolt.AsyncApp:Bolt app is running!
INFO:discord.gateway:Shard ID None has connected to Gateway (Session ID: 1cd3c18eebd447c25c3633df9e26a3de).
INFO:discord.client:logging in using static token
INFO:slack_bolt.AsyncApp:A new session (s_126233602935) has been established
INFO:slack_bolt.AsyncApp:Bolt app is running!
INFO:discord.gateway:Shard ID None has connected to Gateway (Session ID: 20ddb6ccdb2128e0266eb90e34e8a505).
ERROR:discord.client:Ignoring exception in on_message
Traceback (most recent call last):
  File "C:\Users\Gavin Liles\AppData\Local\Programs\Python\Python313\Lib\site-packages\discord\client.py", line 481, in _run_event
    await coro(*args, **kwargs)
  File "C:\Users\Gavin Liles\Documents\codeproject\DiscordBot\DiscordBot\main.py", line 57, in on_message
    await handle_superadmin_commands(message)
  File "C:\Users\Gavin Liles\Documents\codeproject\DiscordBot\DiscordBot\main.py", line 74, in handle_superadmin_commands
    await SuperAdmin.process_tml(message, SUPERADMINCHAT, SUPERADMINROLE, MENTORROLE)
          ~~~~~~~~~~~~~~~~~~~~~~^^^^^^^^^^^^^^^^^^^^^^^^^^^^^^^^^^^^^^^^^^^^^^^^^^^^^
TypeError: process_tml() missing 1 required positional argument: 'MentorRole'
ERROR:discord.client:Ignoring exception in on_message
Traceback (most recent call last):
  File "C:\Users\Gavin Liles\AppData\Local\Programs\Python\Python313\Lib\site-packages\discord\client.py", line 481, in _run_event
    await coro(*args, **kwargs)
  File "C:\Users\Gavin Liles\Documents\codeproject\DiscordBot\DiscordBot\main.py", line 57, in on_message
    await handle_superadmin_commands(message)
  File "C:\Users\Gavin Liles\Documents\codeproject\DiscordBot\DiscordBot\main.py", line 74, in handle_superadmin_commands
    await SuperAdmin.process_tml(message, SUPERADMINCHAT, SUPERADMINROLE, MENTORROLE)
          ~~~~~~~~~~~~~~~~~~~~~~^^^^^^^^^^^^^^^^^^^^^^^^^^^^^^^^^^^^^^^^^^^^^^^^^^^^^
TypeError: process_tml() missing 1 required positional argument: 'MentorRole'
INFO:discord.client:logging in using static token
INFO:slack_bolt.AsyncApp:A new session (s_106439326583) has been established
INFO:slack_bolt.AsyncApp:Bolt app is running!
INFO:discord.gateway:Shard ID None has connected to Gateway (Session ID: 748731c58b895238b0d4dea0f92b80e4).
INFO:discord.client:logging in using static token
INFO:slack_bolt.AsyncApp:A new session (s_94161559620) has been established
INFO:slack_bolt.AsyncApp:Bolt app is running!
INFO:discord.gateway:Shard ID None has connected to Gateway (Session ID: 758a9e8f1ac8e2d3b23ad1bf643c9cff).
INFO:discord.client:logging in using static token
INFO:slack_bolt.AsyncApp:A new session (s_125336169335) has been established
INFO:slack_bolt.AsyncApp:Bolt app is running!
INFO:discord.gateway:Shard ID None has connected to Gateway (Session ID: f75504b8611f752ffcab602b511ba764).
INFO:discord.client:logging in using static token
INFO:slack_bolt.AsyncApp:A new session (s_159821437815) has been established
INFO:slack_bolt.AsyncApp:Bolt app is running!
INFO:discord.gateway:Shard ID None has connected to Gateway (Session ID: 3930b168a4895cf745a1fd8f5bc5bab8).
INFO:discord.client:logging in using static token
INFO:slack_bolt.AsyncApp:A new session (s_137783196535) has been established
INFO:slack_bolt.AsyncApp:Bolt app is running!
INFO:discord.gateway:Shard ID None has connected to Gateway (Session ID: 9e9008e09fb29680c73664aec87c1647).
INFO:discord.client:logging in using static token
INFO:slack_bolt.AsyncApp:A new session (s_97061718924) has been established
INFO:slack_bolt.AsyncApp:Bolt app is running!
INFO:discord.gateway:Shard ID None has connected to Gateway (Session ID: 337a83aba71b7d633e0a49b73d269ee9).
INFO:discord.client:logging in using static token
INFO:slack_bolt.AsyncApp:A new session (s_202444074871) has been established
INFO:slack_bolt.AsyncApp:Bolt app is running!
INFO:discord.gateway:Shard ID None has connected to Gateway (Session ID: c1244975fca4e487af25939ab2582c9a).
INFO:discord.client:logging in using static token
INFO:slack_bolt.AsyncApp:A new session (s_106271951735) has been established
INFO:slack_bolt.AsyncApp:Bolt app is running!
INFO:discord.gateway:Shard ID None has connected to Gateway (Session ID: 779d623ffbadf59778dc0b92df0735a9).
INFO:discord.client:logging in using static token
INFO:slack_bolt.AsyncApp:A new session (s_153618189175) has been established
INFO:slack_bolt.AsyncApp:Bolt app is running!
INFO:discord.gateway:Shard ID None has connected to Gateway (Session ID: 3958f90a98efd0625ac42f64f0e189cb).
INFO:discord.client:logging in using static token
INFO:slack_bolt.AsyncApp:A new session (s_136223653956) has been established
INFO:slack_bolt.AsyncApp:Bolt app is running!
INFO:discord.gateway:Shard ID None has connected to Gateway (Session ID: e9f6d89d4e316b738e14aa70cd316e6b).
INFO:discord.client:logging in using static token
INFO:slack_bolt.AsyncApp:A new session (s_165767105420) has been established
INFO:slack_bolt.AsyncApp:Bolt app is running!
INFO:discord.gateway:Shard ID None has connected to Gateway (Session ID: 18d70a20d3757c50864d6027c846c2fc).
ERROR:discord.client:Ignoring exception in on_message
Traceback (most recent call last):
  File "C:\Users\Gavin Liles\AppData\Local\Programs\Python\Python313\Lib\site-packages\discord\client.py", line 481, in _run_event
    await coro(*args, **kwargs)
  File "C:\Users\Gavin Liles\Documents\codeproject\DiscordBot\DiscordBot\main.py", line 59, in on_message
    data = tomllib.load(infile)
  File "C:\Users\Gavin Liles\AppData\Local\Programs\Python\Python313\Lib\tomllib\_parser.py", line 63, in load
    raise TypeError(
        "File must be opened in binary mode, e.g. use `open('foo.toml', 'rb')`"
    ) from None
TypeError: File must be opened in binary mode, e.g. use `open('foo.toml', 'rb')`
INFO:discord.client:logging in using static token
INFO:slack_bolt.AsyncApp:A new session (s_162686880652) has been established
INFO:slack_bolt.AsyncApp:Bolt app is running!
INFO:discord.gateway:Shard ID None has connected to Gateway (Session ID: 4dfb32955ad2ed8686e5a3a5cd889590).
ERROR:discord.client:Ignoring exception in on_message
Traceback (most recent call last):
  File "C:\Users\Gavin Liles\AppData\Local\Programs\Python\Python313\Lib\site-packages\discord\client.py", line 481, in _run_event
    await coro(*args, **kwargs)
  File "C:\Users\Gavin Liles\Documents\codeproject\DiscordBot\DiscordBot\main.py", line 60, in on_message
    data = tomllib.load(infile)
  File "C:\Users\Gavin Liles\AppData\Local\Programs\Python\Python313\Lib\tomllib\_parser.py", line 63, in load
    raise TypeError(
        "File must be opened in binary mode, e.g. use `open('foo.toml', 'rb')`"
    ) from None
TypeError: File must be opened in binary mode, e.g. use `open('foo.toml', 'rb')`
INFO:discord.client:logging in using static token
INFO:slack_bolt.AsyncApp:A new session (s_157471281036) has been established
INFO:slack_bolt.AsyncApp:Bolt app is running!
INFO:discord.gateway:Shard ID None has connected to Gateway (Session ID: 782b638db68140b9051713af9ca5cd9a).
INFO:discord.client:logging in using static token
INFO:slack_bolt.AsyncApp:A new session (s_120572672908) has been established
INFO:slack_bolt.AsyncApp:Bolt app is running!
INFO:discord.gateway:Shard ID None has connected to Gateway (Session ID: 672b0f29a799b34c2ddec7ebfb473cd1).
INFO:discord.client:logging in using static token
INFO:slack_bolt.AsyncApp:A new session (s_179203447692) has been established
INFO:slack_bolt.AsyncApp:Bolt app is running!
INFO:discord.gateway:Shard ID None has connected to Gateway (Session ID: 290c222ead3da8290703d98aba438c0f).
INFO:discord.client:logging in using static token
INFO:slack_bolt.AsyncApp:A new session (s_123376454540) has been established
INFO:slack_bolt.AsyncApp:Bolt app is running!
INFO:discord.gateway:Shard ID None has connected to Gateway (Session ID: 00bdc85c2c80584f6ea977b60f6e171b).
ERROR:discord.client:Ignoring exception in on_message
Traceback (most recent call last):
  File "C:\Users\Gavin Liles\Documents\codeproject\DiscordBot\DiscordBot\main.py", line 109, in on_message
    await message.delete()
  File "C:\Users\Gavin Liles\AppData\Local\Programs\Python\Python313\Lib\site-packages\discord\message.py", line 1304, in delete
    await self._state.http.delete_message(self.channel.id, self.id)
  File "C:\Users\Gavin Liles\AppData\Local\Programs\Python\Python313\Lib\site-packages\discord\http.py", line 758, in request
    raise NotFound(response, data)
discord.errors.NotFound: 404 Not Found (error code: 10008): Unknown Message

During handling of the above exception, another exception occurred:

Traceback (most recent call last):
  File "C:\Users\Gavin Liles\AppData\Local\Programs\Python\Python313\Lib\site-packages\discord\client.py", line 481, in _run_event
    await coro(*args, **kwargs)
  File "C:\Users\Gavin Liles\Documents\codeproject\DiscordBot\DiscordBot\main.py", line 127, in on_message
    await message.delete()
  File "C:\Users\Gavin Liles\AppData\Local\Programs\Python\Python313\Lib\site-packages\discord\message.py", line 1304, in delete
    await self._state.http.delete_message(self.channel.id, self.id)
  File "C:\Users\Gavin Liles\AppData\Local\Programs\Python\Python313\Lib\site-packages\discord\http.py", line 758, in request
    raise NotFound(response, data)
discord.errors.NotFound: 404 Not Found (error code: 10008): Unknown Message
INFO:discord.client:logging in using static token
INFO:slack_bolt.AsyncApp:A new session (s_141550283660) has been established
INFO:slack_bolt.AsyncApp:Bolt app is running!
INFO:discord.gateway:Shard ID None has connected to Gateway (Session ID: 7790243a3f41594d046c2937d3dd8057).
ERROR:discord.client:Ignoring exception in on_message
Traceback (most recent call last):
  File "C:\Users\Gavin Liles\Documents\codeproject\DiscordBot\DiscordBot\main.py", line 109, in on_message
    await message.delete()
  File "C:\Users\Gavin Liles\AppData\Local\Programs\Python\Python313\Lib\site-packages\discord\message.py", line 1304, in delete
    await self._state.http.delete_message(self.channel.id, self.id)
  File "C:\Users\Gavin Liles\AppData\Local\Programs\Python\Python313\Lib\site-packages\discord\http.py", line 758, in request
    raise NotFound(response, data)
discord.errors.NotFound: 404 Not Found (error code: 10008): Unknown Message

During handling of the above exception, another exception occurred:

Traceback (most recent call last):
  File "C:\Users\Gavin Liles\AppData\Local\Programs\Python\Python313\Lib\site-packages\discord\client.py", line 481, in _run_event
    await coro(*args, **kwargs)
  File "C:\Users\Gavin Liles\Documents\codeproject\DiscordBot\DiscordBot\main.py", line 123, in on_message
    await message.delete()
  File "C:\Users\Gavin Liles\AppData\Local\Programs\Python\Python313\Lib\site-packages\discord\message.py", line 1304, in delete
    await self._state.http.delete_message(self.channel.id, self.id)
  File "C:\Users\Gavin Liles\AppData\Local\Programs\Python\Python313\Lib\site-packages\discord\http.py", line 758, in request
    raise NotFound(response, data)
discord.errors.NotFound: 404 Not Found (error code: 10008): Unknown Message
INFO:discord.client:logging in using static token
INFO:slack_bolt.AsyncApp:A new session (s_154320554892) has been established
INFO:slack_bolt.AsyncApp:Bolt app is running!
INFO:discord.gateway:Shard ID None has connected to Gateway (Session ID: c82375fc14a55b3164ae9322af6f7cf8).
ERROR:discord.client:Ignoring exception in on_message
Traceback (most recent call last):
  File "C:\Users\Gavin Liles\Documents\codeproject\DiscordBot\DiscordBot\main.py", line 109, in on_message
    await message.delete()
  File "C:\Users\Gavin Liles\AppData\Local\Programs\Python\Python313\Lib\site-packages\discord\message.py", line 1304, in delete
    await self._state.http.delete_message(self.channel.id, self.id)
  File "C:\Users\Gavin Liles\AppData\Local\Programs\Python\Python313\Lib\site-packages\discord\http.py", line 758, in request
    raise NotFound(response, data)
discord.errors.NotFound: 404 Not Found (error code: 10008): Unknown Message

During handling of the above exception, another exception occurred:

Traceback (most recent call last):
  File "C:\Users\Gavin Liles\AppData\Local\Programs\Python\Python313\Lib\site-packages\discord\client.py", line 481, in _run_event
    await coro(*args, **kwargs)
  File "C:\Users\Gavin Liles\Documents\codeproject\DiscordBot\DiscordBot\main.py", line 123, in on_message
    await message.delete()
  File "C:\Users\Gavin Liles\AppData\Local\Programs\Python\Python313\Lib\site-packages\discord\message.py", line 1304, in delete
    await self._state.http.delete_message(self.channel.id, self.id)
  File "C:\Users\Gavin Liles\AppData\Local\Programs\Python\Python313\Lib\site-packages\discord\http.py", line 758, in request
    raise NotFound(response, data)
discord.errors.NotFound: 404 Not Found (error code: 10008): Unknown Message
INFO:discord.client:logging in using static token
INFO:slack_bolt.AsyncApp:A new session (s_134919669644) has been established
INFO:slack_bolt.AsyncApp:Bolt app is running!
INFO:discord.gateway:Shard ID None has connected to Gateway (Session ID: 0806a178adf5ce5423f44bca503ae9a1).
INFO:discord.client:logging in using static token
INFO:slack_bolt.AsyncApp:A new session (s_141219422092) has been established
INFO:slack_bolt.AsyncApp:Bolt app is running!
INFO:discord.gateway:Shard ID None has connected to Gateway (Session ID: b9d3032c73699d52489279006fff284b).
INFO:discord.client:logging in using static token
INFO:slack_bolt.AsyncApp:A new session (s_125849153420) has been established
INFO:slack_bolt.AsyncApp:Bolt app is running!
INFO:discord.gateway:Shard ID None has connected to Gateway (Session ID: e3eabaf5a92cb5e1674a56da427f4c00).
INFO:discord.client:logging in using static token
INFO:slack_bolt.AsyncApp:A new session (s_131694391180) has been established
INFO:slack_bolt.AsyncApp:Bolt app is running!
INFO:discord.gateway:Shard ID None has connected to Gateway (Session ID: 03fe92e839c40e81e392b3f901f3546b).
INFO:discord.client:logging in using static token
INFO:slack_bolt.AsyncApp:A new session (s_131939340151) has been established
INFO:slack_bolt.AsyncApp:Bolt app is running!
INFO:discord.gateway:Shard ID None has connected to Gateway (Session ID: 50fc5fcbab83c71812c993b6ce639c04).
ERROR:discord.ext.commands.bot:Ignoring exception in command None
discord.ext.commands.errors.CommandNotFound: Command "GetTokens" is not found
ERROR:discord.ext.commands.bot:Ignoring exception in command None
discord.ext.commands.errors.CommandNotFound: Command "GetTokens" is not found
INFO:discord.client:logging in using static token
INFO:slack_bolt.AsyncApp:A new session (s_117707804556) has been established
INFO:slack_bolt.AsyncApp:Bolt app is running!
INFO:discord.gateway:Shard ID None has connected to Gateway (Session ID: 2f2ad6537a033dc629aca1bb7903568e).
ERROR:discord.ext.commands.bot:Ignoring exception in command None
discord.ext.commands.errors.CommandNotFound: Command "GetTokens" is not found
ERROR:discord.ext.commands.bot:Ignoring exception in command None
discord.ext.commands.errors.CommandNotFound: Command "GetTokens" is not found
ERROR:discord.ext.commands.bot:Ignoring exception in command None
discord.ext.commands.errors.CommandNotFound: Command "GetTokens" is not found
ERROR:discord.ext.commands.bot:Ignoring exception in command None
discord.ext.commands.errors.CommandNotFound: Command "GetTokens" is not found
INFO:discord.client:logging in using static token
INFO:slack_bolt.AsyncApp:A new session (s_96616210316) has been established
INFO:slack_bolt.AsyncApp:Bolt app is running!
INFO:discord.gateway:Shard ID None has connected to Gateway (Session ID: 1cfcecdea7c6fab9c594eea135faf725).
INFO:discord.client:logging in using static token
INFO:slack_bolt.AsyncApp:A new session (s_143195426700) has been established
INFO:slack_bolt.AsyncApp:Bolt app is running!
INFO:discord.gateway:Shard ID None has connected to Gateway (Session ID: d5e61a48ddaf2272bdc191e8864f5052).
ERROR:discord.ext.commands.bot:Ignoring exception in command Links
Traceback (most recent call last):
  File "C:\Users\Gavin Liles\AppData\Local\Programs\Python\Python313\Lib\site-packages\discord\ext\commands\bot.py", line 1366, in invoke
    await ctx.command.invoke(ctx)
  File "C:\Users\Gavin Liles\AppData\Local\Programs\Python\Python313\Lib\site-packages\discord\ext\commands\core.py", line 1021, in invoke
    await self.prepare(ctx)
  File "C:\Users\Gavin Liles\AppData\Local\Programs\Python\Python313\Lib\site-packages\discord\ext\commands\core.py", line 925, in prepare
    if not await self.can_run(ctx):
           ^^^^^^^^^^^^^^^^^^^^^^^
  File "C:\Users\Gavin Liles\AppData\Local\Programs\Python\Python313\Lib\site-packages\discord\ext\commands\core.py", line 1288, in can_run
    return await discord.utils.async_all(predicate(ctx) for predicate in predicates)  # type: ignore
           ^^^^^^^^^^^^^^^^^^^^^^^^^^^^^^^^^^^^^^^^^^^^^^^^^^^^^^^^^^^^^^^^^^^^^^^^^
  File "C:\Users\Gavin Liles\AppData\Local\Programs\Python\Python313\Lib\site-packages\discord\utils.py", line 725, in async_all
    for elem in gen:
                ^^^
  File "C:\Users\Gavin Liles\AppData\Local\Programs\Python\Python313\Lib\site-packages\discord\ext\commands\core.py", line 1288, in <genexpr>
    return await discord.utils.async_all(predicate(ctx) for predicate in predicates)  # type: ignore
                                         ~~~~~~~~~^^^^^
  File "C:\Users\Gavin Liles\AppData\Local\Programs\Python\Python313\Lib\site-packages\discord\ext\commands\core.py", line 2101, in predicate
    raise MissingAnyRole(list(items))
discord.ext.commands.errors.MissingAnyRole: You are missing at least one of the required roles: 'SuperAdmin'
INFO:discord.client:logging in using static token
INFO:slack_bolt.AsyncApp:A new session (s_149862188919) has been established
INFO:slack_bolt.AsyncApp:Bolt app is running!
INFO:discord.gateway:Shard ID None has connected to Gateway (Session ID: 23a7e06465aa72c09fc7152f6a68d2ec).
ERROR:discord.client:Ignoring exception in on_message
Traceback (most recent call last):
  File "C:\Users\Gavin Liles\AppData\Local\Programs\Python\Python313\Lib\site-packages\discord\client.py", line 481, in _run_event
    await coro(*args, **kwargs)
  File "C:\Users\Gavin Liles\Documents\codeproject\DiscordBot\DiscordBot\main.py", line 71, in on_message
    if islink(message.content):
       ~~~~~~^^^^^^^^^^^^^^^^^
  File "C:\Users\Gavin Liles\Documents\codeproject\DiscordBot\DiscordBot\main.py", line 137, in islink
    return bool(re.serach(r'https?://|www\\.',link))
                ^^^^^^^^^
AttributeError: module 're' has no attribute 'serach'. Did you mean: 'search'?
INFO:discord.client:logging in using static token
INFO:slack_bolt.AsyncApp:A new session (s_194125711428) has been established
INFO:slack_bolt.AsyncApp:Bolt app is running!
INFO:discord.gateway:Shard ID None has connected to Gateway (Session ID: abc7e31f513852d987abbb036ccdc413).
ERROR:discord.client:Ignoring exception in on_message
Traceback (most recent call last):
  File "C:\Users\Gavin Liles\AppData\Local\Programs\Python\Python313\Lib\site-packages\discord\client.py", line 481, in _run_event
    await coro(*args, **kwargs)
  File "C:\Users\Gavin Liles\Documents\codeproject\DiscordBot\DiscordBot\main.py", line 71, in on_message
    if islink(message.content):
       ~~~~~~^^^^^^^^^^^^^^^^^
  File "C:\Users\Gavin Liles\Documents\codeproject\DiscordBot\DiscordBot\main.py", line 137, in islink
    return bool(re.serach(r'https?://|www\\.',link))
                ^^^^^^^^^
AttributeError: module 're' has no attribute 'serach'. Did you mean: 'search'?
INFO:discord.client:logging in using static token
INFO:slack_bolt.AsyncApp:A new session (s_125265510263) has been established
INFO:slack_bolt.AsyncApp:Bolt app is running!
INFO:discord.gateway:Shard ID None has connected to Gateway (Session ID: dd868a18f869948e012c2dc4387cfc8b).
ERROR:discord.client:Ignoring exception in on_message
Traceback (most recent call last):
  File "C:\Users\Gavin Liles\AppData\Local\Programs\Python\Python313\Lib\site-packages\discord\client.py", line 481, in _run_event
    await coro(*args, **kwargs)
  File "C:\Users\Gavin Liles\Documents\codeproject\DiscordBot\DiscordBot\main.py", line 71, in on_message
    if islink(message.content):
       ~~~~~~^^^^^^^^^^^^^^^^^
  File "C:\Users\Gavin Liles\Documents\codeproject\DiscordBot\DiscordBot\main.py", line 137, in islink
    return bool(re.serach(r'https?://|www\\.',link))
                ^^^^^^^^^
AttributeError: module 're' has no attribute 'serach'. Did you mean: 'search'?
ERROR:discord.client:Ignoring exception in on_message
Traceback (most recent call last):
  File "C:\Users\Gavin Liles\AppData\Local\Programs\Python\Python313\Lib\site-packages\discord\client.py", line 481, in _run_event
    await coro(*args, **kwargs)
  File "C:\Users\Gavin Liles\Documents\codeproject\DiscordBot\DiscordBot\main.py", line 71, in on_message
    if islink(message.content):
       ~~~~~~^^^^^^^^^^^^^^^^^
  File "C:\Users\Gavin Liles\Documents\codeproject\DiscordBot\DiscordBot\main.py", line 137, in islink
    return bool(re.serach(r'https?://|www\\.',link))
                ^^^^^^^^^
AttributeError: module 're' has no attribute 'serach'. Did you mean: 'search'?
INFO:discord.client:logging in using static token
INFO:slack_bolt.AsyncApp:A new session (s_133223011191) has been established
INFO:slack_bolt.AsyncApp:Bolt app is running!
INFO:discord.gateway:Shard ID None has connected to Gateway (Session ID: 4797a0f833c41c8ffb141a8d2b9469ab).
ERROR:discord.client:Ignoring exception in on_message
Traceback (most recent call last):
  File "C:\Users\Gavin Liles\AppData\Local\Programs\Python\Python313\Lib\site-packages\discord\client.py", line 481, in _run_event
    await coro(*args, **kwargs)
  File "C:\Users\Gavin Liles\Documents\codeproject\DiscordBot\DiscordBot\main.py", line 71, in on_message
    if islink(message.content):
       ~~~~~~^^^^^^^^^^^^^^^^^
  File "C:\Users\Gavin Liles\Documents\codeproject\DiscordBot\DiscordBot\main.py", line 137, in islink
    return bool(re.serach(r'https?://|www\\.',link))
                ^^^^^^^^^
AttributeError: module 're' has no attribute 'serach'. Did you mean: 'search'?
ERROR:discord.client:Ignoring exception in on_message
Traceback (most recent call last):
  File "C:\Users\Gavin Liles\AppData\Local\Programs\Python\Python313\Lib\site-packages\discord\client.py", line 481, in _run_event
    await coro(*args, **kwargs)
  File "C:\Users\Gavin Liles\Documents\codeproject\DiscordBot\DiscordBot\main.py", line 71, in on_message
    if islink(message.content):
       ~~~~~~^^^^^^^^^^^^^^^^^
  File "C:\Users\Gavin Liles\Documents\codeproject\DiscordBot\DiscordBot\main.py", line 137, in islink
    return bool(re.serach(r'https?://|www\\.',link))
                ^^^^^^^^^
AttributeError: module 're' has no attribute 'serach'. Did you mean: 'search'?
ERROR:discord.client:Ignoring exception in on_message
Traceback (most recent call last):
  File "C:\Users\Gavin Liles\AppData\Local\Programs\Python\Python313\Lib\site-packages\discord\client.py", line 481, in _run_event
    await coro(*args, **kwargs)
  File "C:\Users\Gavin Liles\Documents\codeproject\DiscordBot\DiscordBot\main.py", line 71, in on_message
    if islink(message.content):
       ~~~~~~^^^^^^^^^^^^^^^^^
  File "C:\Users\Gavin Liles\Documents\codeproject\DiscordBot\DiscordBot\main.py", line 137, in islink
    return bool(re.serach(r'https?://|www\\.',link))
                ^^^^^^^^^
AttributeError: module 're' has no attribute 'serach'. Did you mean: 'search'?
ERROR:discord.client:Ignoring exception in on_message
Traceback (most recent call last):
  File "C:\Users\Gavin Liles\AppData\Local\Programs\Python\Python313\Lib\site-packages\discord\client.py", line 481, in _run_event
    await coro(*args, **kwargs)
  File "C:\Users\Gavin Liles\Documents\codeproject\DiscordBot\DiscordBot\main.py", line 71, in on_message
    if islink(message.content):
       ~~~~~~^^^^^^^^^^^^^^^^^
  File "C:\Users\Gavin Liles\Documents\codeproject\DiscordBot\DiscordBot\main.py", line 137, in islink
    return bool(re.serach(r'https?://|www\\.',link))
                ^^^^^^^^^
AttributeError: module 're' has no attribute 'serach'. Did you mean: 'search'?
ERROR:discord.client:Ignoring exception in on_message
Traceback (most recent call last):
  File "C:\Users\Gavin Liles\AppData\Local\Programs\Python\Python313\Lib\site-packages\discord\client.py", line 481, in _run_event
    await coro(*args, **kwargs)
  File "C:\Users\Gavin Liles\Documents\codeproject\DiscordBot\DiscordBot\main.py", line 71, in on_message
    if islink(message.content):
       ~~~~~~^^^^^^^^^^^^^^^^^
  File "C:\Users\Gavin Liles\Documents\codeproject\DiscordBot\DiscordBot\main.py", line 137, in islink
    return bool(re.serach(r'https?://|www\\.',link))
                ^^^^^^^^^
AttributeError: module 're' has no attribute 'serach'. Did you mean: 'search'?
INFO:discord.client:logging in using static token
INFO:slack_bolt.AsyncApp:A new session (s_96234844023) has been established
INFO:slack_bolt.AsyncApp:Bolt app is running!
INFO:discord.gateway:Shard ID None has connected to Gateway (Session ID: 831b6174d804e98a777f6da1f00471f2).
ERROR:discord.client:Ignoring exception in on_message
Traceback (most recent call last):
  File "C:\Users\Gavin Liles\AppData\Local\Programs\Python\Python313\Lib\site-packages\discord\client.py", line 481, in _run_event
    await coro(*args, **kwargs)
  File "C:\Users\Gavin Liles\Documents\codeproject\DiscordBot\DiscordBot\main.py", line 71, in on_message
    if islink(message.attachments):
       ~~~~~~^^^^^^^^^^^^^^^^^^^^^
  File "C:\Users\Gavin Liles\Documents\codeproject\DiscordBot\DiscordBot\main.py", line 137, in islink
    return bool(re.serach(r'https?://|www\\.',link))
                ^^^^^^^^^
AttributeError: module 're' has no attribute 'serach'. Did you mean: 'search'?
ERROR:discord.client:Ignoring exception in on_message
Traceback (most recent call last):
  File "C:\Users\Gavin Liles\AppData\Local\Programs\Python\Python313\Lib\site-packages\discord\client.py", line 481, in _run_event
    await coro(*args, **kwargs)
  File "C:\Users\Gavin Liles\Documents\codeproject\DiscordBot\DiscordBot\main.py", line 71, in on_message
    if islink(message.attachments):
       ~~~~~~^^^^^^^^^^^^^^^^^^^^^
  File "C:\Users\Gavin Liles\Documents\codeproject\DiscordBot\DiscordBot\main.py", line 137, in islink
    return bool(re.serach(r'https?://|www\\.',link))
                ^^^^^^^^^
AttributeError: module 're' has no attribute 'serach'. Did you mean: 'search'?
INFO:discord.client:logging in using static token
INFO:slack_bolt.AsyncApp:A new session (s_108171118660) has been established
INFO:slack_bolt.AsyncApp:Bolt app is running!
INFO:discord.gateway:Shard ID None has connected to Gateway (Session ID: 7dea1648ff91515ac61fe30265334c56).
ERROR:discord.ext.commands.bot:Ignoring exception in command Links
Traceback (most recent call last):
  File "C:\Users\Gavin Liles\AppData\Local\Programs\Python\Python313\Lib\site-packages\discord\ext\commands\bot.py", line 1366, in invoke
    await ctx.command.invoke(ctx)
  File "C:\Users\Gavin Liles\AppData\Local\Programs\Python\Python313\Lib\site-packages\discord\ext\commands\core.py", line 1021, in invoke
    await self.prepare(ctx)
  File "C:\Users\Gavin Liles\AppData\Local\Programs\Python\Python313\Lib\site-packages\discord\ext\commands\core.py", line 938, in prepare
    await self._parse_arguments(ctx)
  File "C:\Users\Gavin Liles\AppData\Local\Programs\Python\Python313\Lib\site-packages\discord\ext\commands\core.py", line 845, in _parse_arguments
    transformed = await self.transform(ctx, param, attachments)
                  ^^^^^^^^^^^^^^^^^^^^^^^^^^^^^^^^^^^^^^^^^^^^^
  File "C:\Users\Gavin Liles\AppData\Local\Programs\Python\Python313\Lib\site-packages\discord\ext\commands\core.py", line 697, in transform
    raise MissingRequiredArgument(param)
discord.ext.commands.errors.MissingRequiredArgument: setting is a required argument that is missing.
ERROR:discord.ext.commands.bot:Ignoring exception in command Links
Traceback (most recent call last):
  File "C:\Users\Gavin Liles\AppData\Local\Programs\Python\Python313\Lib\site-packages\discord\ext\commands\bot.py", line 1366, in invoke
    await ctx.command.invoke(ctx)
  File "C:\Users\Gavin Liles\AppData\Local\Programs\Python\Python313\Lib\site-packages\discord\ext\commands\core.py", line 1021, in invoke
    await self.prepare(ctx)
  File "C:\Users\Gavin Liles\AppData\Local\Programs\Python\Python313\Lib\site-packages\discord\ext\commands\core.py", line 938, in prepare
    await self._parse_arguments(ctx)
  File "C:\Users\Gavin Liles\AppData\Local\Programs\Python\Python313\Lib\site-packages\discord\ext\commands\core.py", line 845, in _parse_arguments
    transformed = await self.transform(ctx, param, attachments)
                  ^^^^^^^^^^^^^^^^^^^^^^^^^^^^^^^^^^^^^^^^^^^^^
  File "C:\Users\Gavin Liles\AppData\Local\Programs\Python\Python313\Lib\site-packages\discord\ext\commands\core.py", line 697, in transform
    raise MissingRequiredArgument(param)
discord.ext.commands.errors.MissingRequiredArgument: setting is a required argument that is missing.
INFO:discord.client:logging in using static token
INFO:slack_bolt.AsyncApp:A new session (s_97155169143) has been established
INFO:slack_bolt.AsyncApp:Bolt app is running!
INFO:discord.gateway:Shard ID None has connected to Gateway (Session ID: 18177645d6d61dd633f8fab2d33d7518).
ERROR:discord.ext.commands.bot:Ignoring exception in command Remove
Traceback (most recent call last):
  File "C:\Users\Gavin Liles\AppData\Local\Programs\Python\Python313\Lib\site-packages\discord\ext\commands\bot.py", line 1366, in invoke
    await ctx.command.invoke(ctx)
  File "C:\Users\Gavin Liles\AppData\Local\Programs\Python\Python313\Lib\site-packages\discord\ext\commands\core.py", line 1021, in invoke
    await self.prepare(ctx)
  File "C:\Users\Gavin Liles\AppData\Local\Programs\Python\Python313\Lib\site-packages\discord\ext\commands\core.py", line 938, in prepare
    await self._parse_arguments(ctx)
  File "C:\Users\Gavin Liles\AppData\Local\Programs\Python\Python313\Lib\site-packages\discord\ext\commands\core.py", line 845, in _parse_arguments
    transformed = await self.transform(ctx, param, attachments)
                  ^^^^^^^^^^^^^^^^^^^^^^^^^^^^^^^^^^^^^^^^^^^^^
  File "C:\Users\Gavin Liles\AppData\Local\Programs\Python\Python313\Lib\site-packages\discord\ext\commands\core.py", line 715, in transform
    return await run_converters(ctx, converter, argument, param)  # type: ignore
           ^^^^^^^^^^^^^^^^^^^^^^^^^^^^^^^^^^^^^^^^^^^^^^^^^^^^^
  File "C:\Users\Gavin Liles\AppData\Local\Programs\Python\Python313\Lib\site-packages\discord\ext\commands\converter.py", line 1444, in run_converters
    return await _actual_conversion(ctx, converter, argument, param)
           ^^^^^^^^^^^^^^^^^^^^^^^^^^^^^^^^^^^^^^^^^^^^^^^^^^^^^^^^^
  File "C:\Users\Gavin Liles\AppData\Local\Programs\Python\Python313\Lib\site-packages\discord\ext\commands\converter.py", line 1326, in _actual_conversion
    return await converter().convert(ctx, argument)
           ^^^^^^^^^^^^^^^^^^^^^^^^^^^^^^^^^^^^^^^^
  File "C:\Users\Gavin Liles\AppData\Local\Programs\Python\Python313\Lib\site-packages\discord\ext\commands\converter.py", line 281, in convert
    raise MemberNotFound(argument)
discord.ext.commands.errors.MemberNotFound: Member "@Ty1103" not found.
ERROR:discord.ext.commands.bot:Ignoring exception in command Remove
Traceback (most recent call last):
  File "C:\Users\Gavin Liles\AppData\Local\Programs\Python\Python313\Lib\site-packages\discord\ext\commands\bot.py", line 1366, in invoke
    await ctx.command.invoke(ctx)
  File "C:\Users\Gavin Liles\AppData\Local\Programs\Python\Python313\Lib\site-packages\discord\ext\commands\core.py", line 1021, in invoke
    await self.prepare(ctx)
  File "C:\Users\Gavin Liles\AppData\Local\Programs\Python\Python313\Lib\site-packages\discord\ext\commands\core.py", line 938, in prepare
    await self._parse_arguments(ctx)
  File "C:\Users\Gavin Liles\AppData\Local\Programs\Python\Python313\Lib\site-packages\discord\ext\commands\core.py", line 845, in _parse_arguments
    transformed = await self.transform(ctx, param, attachments)
                  ^^^^^^^^^^^^^^^^^^^^^^^^^^^^^^^^^^^^^^^^^^^^^
  File "C:\Users\Gavin Liles\AppData\Local\Programs\Python\Python313\Lib\site-packages\discord\ext\commands\core.py", line 715, in transform
    return await run_converters(ctx, converter, argument, param)  # type: ignore
           ^^^^^^^^^^^^^^^^^^^^^^^^^^^^^^^^^^^^^^^^^^^^^^^^^^^^^
  File "C:\Users\Gavin Liles\AppData\Local\Programs\Python\Python313\Lib\site-packages\discord\ext\commands\converter.py", line 1444, in run_converters
    return await _actual_conversion(ctx, converter, argument, param)
           ^^^^^^^^^^^^^^^^^^^^^^^^^^^^^^^^^^^^^^^^^^^^^^^^^^^^^^^^^
  File "C:\Users\Gavin Liles\AppData\Local\Programs\Python\Python313\Lib\site-packages\discord\ext\commands\converter.py", line 1326, in _actual_conversion
    return await converter().convert(ctx, argument)
           ^^^^^^^^^^^^^^^^^^^^^^^^^^^^^^^^^^^^^^^^
  File "C:\Users\Gavin Liles\AppData\Local\Programs\Python\Python313\Lib\site-packages\discord\ext\commands\converter.py", line 281, in convert
    raise MemberNotFound(argument)
discord.ext.commands.errors.MemberNotFound: Member "@Ty1103" not found.
INFO:discord.client:logging in using static token
INFO:slack_bolt.AsyncApp:A new session (s_116527082359) has been established
INFO:slack_bolt.AsyncApp:Bolt app is running!
INFO:discord.gateway:Shard ID None has connected to Gateway (Session ID: 4fbd7bc85465e8243ed766ee5ee4d906).
INFO:discord.client:logging in using static token
INFO:slack_bolt.AsyncApp:A new session (s_170115237751) has been established
INFO:slack_bolt.AsyncApp:Bolt app is running!
INFO:discord.gateway:Shard ID None has connected to Gateway (Session ID: 5ed1ccb8d99671c8f4f72bf7e6c5f2b8).
ERROR:discord.ext.commands.bot:Ignoring exception in command Remove
Traceback (most recent call last):
  File "C:\Users\Gavin Liles\AppData\Local\Programs\Python\Python313\Lib\site-packages\discord\ext\commands\core.py", line 235, in wrapped
    ret = await coro(*args, **kwargs)
          ^^^^^^^^^^^^^^^^^^^^^^^^^^^
  File "C:\Users\Gavin Liles\Documents\codeproject\DiscordBot\DiscordBot\main.py", line 97, in Remove
    await Commands.Remove(ctx, member, group_names=group_names)
  File "C:\Users\Gavin Liles\Documents\codeproject\DiscordBot\DiscordBot\Commands.py", line 244, in Remove
    role = discord.utils.get(ctx.guild.roles, name=group)
                                                   ^^^^^
NameError: name 'group' is not defined

The above exception was the direct cause of the following exception:

Traceback (most recent call last):
  File "C:\Users\Gavin Liles\AppData\Local\Programs\Python\Python313\Lib\site-packages\discord\ext\commands\bot.py", line 1366, in invoke
    await ctx.command.invoke(ctx)
  File "C:\Users\Gavin Liles\AppData\Local\Programs\Python\Python313\Lib\site-packages\discord\ext\commands\core.py", line 1029, in invoke
    await injected(*ctx.args, **ctx.kwargs)  # type: ignore
    ^^^^^^^^^^^^^^^^^^^^^^^^^^^^^^^^^^^^^^^
  File "C:\Users\Gavin Liles\AppData\Local\Programs\Python\Python313\Lib\site-packages\discord\ext\commands\core.py", line 244, in wrapped
    raise CommandInvokeError(exc) from exc
discord.ext.commands.errors.CommandInvokeError: Command raised an exception: NameError: name 'group' is not defined
ERROR:discord.ext.commands.bot:Ignoring exception in command Remove
Traceback (most recent call last):
  File "C:\Users\Gavin Liles\AppData\Local\Programs\Python\Python313\Lib\site-packages\discord\ext\commands\bot.py", line 1366, in invoke
    await ctx.command.invoke(ctx)
  File "C:\Users\Gavin Liles\AppData\Local\Programs\Python\Python313\Lib\site-packages\discord\ext\commands\core.py", line 1021, in invoke
    await self.prepare(ctx)
  File "C:\Users\Gavin Liles\AppData\Local\Programs\Python\Python313\Lib\site-packages\discord\ext\commands\core.py", line 938, in prepare
    await self._parse_arguments(ctx)
  File "C:\Users\Gavin Liles\AppData\Local\Programs\Python\Python313\Lib\site-packages\discord\ext\commands\core.py", line 845, in _parse_arguments
    transformed = await self.transform(ctx, param, attachments)
                  ^^^^^^^^^^^^^^^^^^^^^^^^^^^^^^^^^^^^^^^^^^^^^
  File "C:\Users\Gavin Liles\AppData\Local\Programs\Python\Python313\Lib\site-packages\discord\ext\commands\core.py", line 715, in transform
    return await run_converters(ctx, converter, argument, param)  # type: ignore
           ^^^^^^^^^^^^^^^^^^^^^^^^^^^^^^^^^^^^^^^^^^^^^^^^^^^^^
  File "C:\Users\Gavin Liles\AppData\Local\Programs\Python\Python313\Lib\site-packages\discord\ext\commands\converter.py", line 1444, in run_converters
    return await _actual_conversion(ctx, converter, argument, param)
           ^^^^^^^^^^^^^^^^^^^^^^^^^^^^^^^^^^^^^^^^^^^^^^^^^^^^^^^^^
  File "C:\Users\Gavin Liles\AppData\Local\Programs\Python\Python313\Lib\site-packages\discord\ext\commands\converter.py", line 1326, in _actual_conversion
    return await converter().convert(ctx, argument)
           ^^^^^^^^^^^^^^^^^^^^^^^^^^^^^^^^^^^^^^^^
  File "C:\Users\Gavin Liles\AppData\Local\Programs\Python\Python313\Lib\site-packages\discord\ext\commands\converter.py", line 281, in convert
    raise MemberNotFound(argument)
discord.ext.commands.errors.MemberNotFound: Member "@Ty1103" not found.
ERROR:discord.ext.commands.bot:Ignoring exception in command Remove
Traceback (most recent call last):
  File "C:\Users\Gavin Liles\AppData\Local\Programs\Python\Python313\Lib\site-packages\discord\ext\commands\core.py", line 235, in wrapped
    ret = await coro(*args, **kwargs)
          ^^^^^^^^^^^^^^^^^^^^^^^^^^^
  File "C:\Users\Gavin Liles\Documents\codeproject\DiscordBot\DiscordBot\main.py", line 97, in Remove
    await Commands.Remove(ctx, member, group_names=group_names)
  File "C:\Users\Gavin Liles\Documents\codeproject\DiscordBot\DiscordBot\Commands.py", line 244, in Remove
    role = discord.utils.get(ctx.guild.roles, name=group)
                                                   ^^^^^
NameError: name 'group' is not defined

The above exception was the direct cause of the following exception:

Traceback (most recent call last):
  File "C:\Users\Gavin Liles\AppData\Local\Programs\Python\Python313\Lib\site-packages\discord\ext\commands\bot.py", line 1366, in invoke
    await ctx.command.invoke(ctx)
  File "C:\Users\Gavin Liles\AppData\Local\Programs\Python\Python313\Lib\site-packages\discord\ext\commands\core.py", line 1029, in invoke
    await injected(*ctx.args, **ctx.kwargs)  # type: ignore
    ^^^^^^^^^^^^^^^^^^^^^^^^^^^^^^^^^^^^^^^
  File "C:\Users\Gavin Liles\AppData\Local\Programs\Python\Python313\Lib\site-packages\discord\ext\commands\core.py", line 244, in wrapped
    raise CommandInvokeError(exc) from exc
discord.ext.commands.errors.CommandInvokeError: Command raised an exception: NameError: name 'group' is not defined
INFO:discord.client:logging in using static token
INFO:slack_bolt.AsyncApp:A new session (s_159474730871) has been established
INFO:slack_bolt.AsyncApp:Bolt app is running!
INFO:discord.gateway:Shard ID None has connected to Gateway (Session ID: 8bac07d48fe0f50d31d49b17af821b37).
INFO:discord.client:logging in using static token
INFO:slack_bolt.AsyncApp:A new session (s_153384311671) has been established
INFO:slack_bolt.AsyncApp:Bolt app is running!
INFO:discord.gateway:Shard ID None has connected to Gateway (Session ID: 84903995898ac7eb823ec8c634fd4867).
ERROR:discord.ext.commands.bot:Ignoring exception in command Links
Traceback (most recent call last):
  File "C:\Users\Gavin Liles\AppData\Local\Programs\Python\Python313\Lib\site-packages\discord\ext\commands\bot.py", line 1366, in invoke
    await ctx.command.invoke(ctx)
  File "C:\Users\Gavin Liles\AppData\Local\Programs\Python\Python313\Lib\site-packages\discord\ext\commands\core.py", line 1021, in invoke
    await self.prepare(ctx)
  File "C:\Users\Gavin Liles\AppData\Local\Programs\Python\Python313\Lib\site-packages\discord\ext\commands\core.py", line 938, in prepare
    await self._parse_arguments(ctx)
  File "C:\Users\Gavin Liles\AppData\Local\Programs\Python\Python313\Lib\site-packages\discord\ext\commands\core.py", line 845, in _parse_arguments
    transformed = await self.transform(ctx, param, attachments)
                  ^^^^^^^^^^^^^^^^^^^^^^^^^^^^^^^^^^^^^^^^^^^^^
  File "C:\Users\Gavin Liles\AppData\Local\Programs\Python\Python313\Lib\site-packages\discord\ext\commands\core.py", line 697, in transform
    raise MissingRequiredArgument(param)
discord.ext.commands.errors.MissingRequiredArgument: setting is a required argument that is missing.
INFO:discord.client:logging in using static token
INFO:slack_bolt.AsyncApp:A new session (s_116022054775) has been established
INFO:slack_bolt.AsyncApp:Bolt app is running!
INFO:discord.gateway:Shard ID None has connected to Gateway (Session ID: 148187c9ca46dc587bc5b5fe55e19504).
ERROR:discord.ext.commands.bot:Ignoring exception in command Links
Traceback (most recent call last):
  File "C:\Users\Gavin Liles\AppData\Local\Programs\Python\Python313\Lib\site-packages\discord\ext\commands\bot.py", line 1366, in invoke
    await ctx.command.invoke(ctx)
  File "C:\Users\Gavin Liles\AppData\Local\Programs\Python\Python313\Lib\site-packages\discord\ext\commands\core.py", line 1021, in invoke
    await self.prepare(ctx)
  File "C:\Users\Gavin Liles\AppData\Local\Programs\Python\Python313\Lib\site-packages\discord\ext\commands\core.py", line 925, in prepare
    if not await self.can_run(ctx):
           ^^^^^^^^^^^^^^^^^^^^^^^
  File "C:\Users\Gavin Liles\AppData\Local\Programs\Python\Python313\Lib\site-packages\discord\ext\commands\core.py", line 1288, in can_run
    return await discord.utils.async_all(predicate(ctx) for predicate in predicates)  # type: ignore
           ^^^^^^^^^^^^^^^^^^^^^^^^^^^^^^^^^^^^^^^^^^^^^^^^^^^^^^^^^^^^^^^^^^^^^^^^^
  File "C:\Users\Gavin Liles\AppData\Local\Programs\Python\Python313\Lib\site-packages\discord\utils.py", line 725, in async_all
    for elem in gen:
                ^^^
  File "C:\Users\Gavin Liles\AppData\Local\Programs\Python\Python313\Lib\site-packages\discord\ext\commands\core.py", line 1288, in <genexpr>
    return await discord.utils.async_all(predicate(ctx) for predicate in predicates)  # type: ignore
                                         ~~~~~~~~~^^^^^
  File "C:\Users\Gavin Liles\AppData\Local\Programs\Python\Python313\Lib\site-packages\discord\ext\commands\core.py", line 2101, in predicate
    raise MissingAnyRole(list(items))
discord.ext.commands.errors.MissingAnyRole: You are missing at least one of the required roles: 
INFO:discord.client:logging in using static token
INFO:slack_bolt.AsyncApp:A new session (s_145781922679) has been established
INFO:slack_bolt.AsyncApp:Bolt app is running!
INFO:discord.gateway:Shard ID None has connected to Gateway (Session ID: a67942e9242d89652f3460002226e193).
INFO:discord.client:logging in using static token
INFO:slack_bolt.AsyncApp:A new session (s_123222683511) has been established
INFO:slack_bolt.AsyncApp:Bolt app is running!
INFO:discord.gateway:Shard ID None has connected to Gateway (Session ID: 7092fe901b3c265c3835e838370c55bd).
ERROR:discord.ext.commands.bot:Ignoring exception in command Links
Traceback (most recent call last):
  File "C:\Users\Gavin Liles\AppData\Local\Programs\Python\Python313\Lib\site-packages\discord\ext\commands\bot.py", line 1366, in invoke
    await ctx.command.invoke(ctx)
  File "C:\Users\Gavin Liles\AppData\Local\Programs\Python\Python313\Lib\site-packages\discord\ext\commands\core.py", line 1021, in invoke
    await self.prepare(ctx)
  File "C:\Users\Gavin Liles\AppData\Local\Programs\Python\Python313\Lib\site-packages\discord\ext\commands\core.py", line 938, in prepare
    await self._parse_arguments(ctx)
  File "C:\Users\Gavin Liles\AppData\Local\Programs\Python\Python313\Lib\site-packages\discord\ext\commands\core.py", line 845, in _parse_arguments
    transformed = await self.transform(ctx, param, attachments)
                  ^^^^^^^^^^^^^^^^^^^^^^^^^^^^^^^^^^^^^^^^^^^^^
  File "C:\Users\Gavin Liles\AppData\Local\Programs\Python\Python313\Lib\site-packages\discord\ext\commands\core.py", line 697, in transform
    raise MissingRequiredArgument(param)
discord.ext.commands.errors.MissingRequiredArgument: setting is a required argument that is missing.
INFO:discord.client:logging in using static token
INFO:slack_bolt.AsyncApp:A new session (s_142622453623) has been established
INFO:slack_bolt.AsyncApp:Bolt app is running!
INFO:discord.gateway:Shard ID None has connected to Gateway (Session ID: 1d4a14e4967b8e6a02e08438aff117a3).
ERROR:discord.ext.commands.bot:Ignoring exception in command Links
Traceback (most recent call last):
  File "C:\Users\Gavin Liles\AppData\Local\Programs\Python\Python313\Lib\site-packages\discord\ext\commands\bot.py", line 1366, in invoke
    await ctx.command.invoke(ctx)
  File "C:\Users\Gavin Liles\AppData\Local\Programs\Python\Python313\Lib\site-packages\discord\ext\commands\core.py", line 1021, in invoke
    await self.prepare(ctx)
  File "C:\Users\Gavin Liles\AppData\Local\Programs\Python\Python313\Lib\site-packages\discord\ext\commands\core.py", line 938, in prepare
    await self._parse_arguments(ctx)
  File "C:\Users\Gavin Liles\AppData\Local\Programs\Python\Python313\Lib\site-packages\discord\ext\commands\core.py", line 845, in _parse_arguments
    transformed = await self.transform(ctx, param, attachments)
                  ^^^^^^^^^^^^^^^^^^^^^^^^^^^^^^^^^^^^^^^^^^^^^
  File "C:\Users\Gavin Liles\AppData\Local\Programs\Python\Python313\Lib\site-packages\discord\ext\commands\core.py", line 697, in transform
    raise MissingRequiredArgument(param)
discord.ext.commands.errors.MissingRequiredArgument: setting is a required argument that is missing.
ERROR:discord.ext.commands.bot:Ignoring exception in command Links
Traceback (most recent call last):
  File "C:\Users\Gavin Liles\AppData\Local\Programs\Python\Python313\Lib\site-packages\discord\ext\commands\bot.py", line 1366, in invoke
    await ctx.command.invoke(ctx)
  File "C:\Users\Gavin Liles\AppData\Local\Programs\Python\Python313\Lib\site-packages\discord\ext\commands\core.py", line 1021, in invoke
    await self.prepare(ctx)
  File "C:\Users\Gavin Liles\AppData\Local\Programs\Python\Python313\Lib\site-packages\discord\ext\commands\core.py", line 938, in prepare
    await self._parse_arguments(ctx)
  File "C:\Users\Gavin Liles\AppData\Local\Programs\Python\Python313\Lib\site-packages\discord\ext\commands\core.py", line 845, in _parse_arguments
    transformed = await self.transform(ctx, param, attachments)
                  ^^^^^^^^^^^^^^^^^^^^^^^^^^^^^^^^^^^^^^^^^^^^^
  File "C:\Users\Gavin Liles\AppData\Local\Programs\Python\Python313\Lib\site-packages\discord\ext\commands\core.py", line 697, in transform
    raise MissingRequiredArgument(param)
discord.ext.commands.errors.MissingRequiredArgument: setting is a required argument that is missing.
INFO:discord.client:logging in using static token
INFO:slack_bolt.AsyncApp:A new session (s_93639661431) has been established
INFO:slack_bolt.AsyncApp:Bolt app is running!
INFO:discord.gateway:Shard ID None has connected to Gateway (Session ID: 780a507f628479d9e81149e417552204).
ERROR:discord.ext.commands.bot:Ignoring exception in command Links
Traceback (most recent call last):
  File "C:\Users\Gavin Liles\AppData\Local\Programs\Python\Python313\Lib\site-packages\discord\ext\commands\core.py", line 235, in wrapped
    ret = await coro(*args, **kwargs)
          ^^^^^^^^^^^^^^^^^^^^^^^^^^^
  File "C:\Users\Gavin Liles\Documents\codeproject\DiscordBot\DiscordBot\main.py", line 101, in Links
    await Commands.Links(ctx, link_control, setting)
          ~~~~~~~~~~~~~~^^^^^^^^^^^^^^^^^^^^^^^^^^^^
TypeError: Links() takes 2 positional arguments but 3 were given

The above exception was the direct cause of the following exception:

Traceback (most recent call last):
  File "C:\Users\Gavin Liles\AppData\Local\Programs\Python\Python313\Lib\site-packages\discord\ext\commands\bot.py", line 1366, in invoke
    await ctx.command.invoke(ctx)
  File "C:\Users\Gavin Liles\AppData\Local\Programs\Python\Python313\Lib\site-packages\discord\ext\commands\core.py", line 1029, in invoke
    await injected(*ctx.args, **ctx.kwargs)  # type: ignore
    ^^^^^^^^^^^^^^^^^^^^^^^^^^^^^^^^^^^^^^^
  File "C:\Users\Gavin Liles\AppData\Local\Programs\Python\Python313\Lib\site-packages\discord\ext\commands\core.py", line 244, in wrapped
    raise CommandInvokeError(exc) from exc
discord.ext.commands.errors.CommandInvokeError: Command raised an exception: TypeError: Links() takes 2 positional arguments but 3 were given
ERROR:discord.ext.commands.bot:Ignoring exception in command None
discord.ext.commands.errors.CommandNotFound: Command "clear" is not found
INFO:discord.client:logging in using static token
INFO:slack_bolt.AsyncApp:A new session (s_160316100471) has been established
INFO:slack_bolt.AsyncApp:Bolt app is running!
INFO:discord.gateway:Shard ID None has connected to Gateway (Session ID: 5717785d2d36514702fad3d91b2fd210).
ERROR:discord.ext.commands.bot:Ignoring exception in command Links
Traceback (most recent call last):
  File "C:\Users\Gavin Liles\AppData\Local\Programs\Python\Python313\Lib\site-packages\discord\ext\commands\core.py", line 235, in wrapped
    ret = await coro(*args, **kwargs)
          ^^^^^^^^^^^^^^^^^^^^^^^^^^^
  File "C:\Users\Gavin Liles\Documents\codeproject\DiscordBot\DiscordBot\main.py", line 101, in Links
    await Commands.Links(ctx, setting)
  File "C:\Users\Gavin Liles\Documents\codeproject\DiscordBot\DiscordBot\Commands.py", line 86, in Links
    role = discord.utils.get(ctx.guild.roles, name=role_name)
                                                   ^^^^^^^^^
NameError: name 'role_name' is not defined

The above exception was the direct cause of the following exception:

Traceback (most recent call last):
  File "C:\Users\Gavin Liles\AppData\Local\Programs\Python\Python313\Lib\site-packages\discord\ext\commands\bot.py", line 1366, in invoke
    await ctx.command.invoke(ctx)
  File "C:\Users\Gavin Liles\AppData\Local\Programs\Python\Python313\Lib\site-packages\discord\ext\commands\core.py", line 1029, in invoke
    await injected(*ctx.args, **ctx.kwargs)  # type: ignore
    ^^^^^^^^^^^^^^^^^^^^^^^^^^^^^^^^^^^^^^^
  File "C:\Users\Gavin Liles\AppData\Local\Programs\Python\Python313\Lib\site-packages\discord\ext\commands\core.py", line 244, in wrapped
    raise CommandInvokeError(exc) from exc
discord.ext.commands.errors.CommandInvokeError: Command raised an exception: NameError: name 'role_name' is not defined
INFO:discord.client:logging in using static token
INFO:slack_bolt.AsyncApp:A new session (s_110723532663) has been established
INFO:slack_bolt.AsyncApp:Bolt app is running!
INFO:discord.gateway:Shard ID None has connected to Gateway (Session ID: 72b5559d0b5aeff38c440abe80e8b7cf).
ERROR:discord.ext.commands.bot:Ignoring exception in command Links
Traceback (most recent call last):
  File "C:\Users\Gavin Liles\AppData\Local\Programs\Python\Python313\Lib\site-packages\discord\ext\commands\core.py", line 235, in wrapped
    ret = await coro(*args, **kwargs)
          ^^^^^^^^^^^^^^^^^^^^^^^^^^^
  File "C:\Users\Gavin Liles\Documents\codeproject\DiscordBot\DiscordBot\main.py", line 101, in Links
    await Commands.Links(ctx, setting)
  File "C:\Users\Gavin Liles\Documents\codeproject\DiscordBot\DiscordBot\Commands.py", line 96, in Links
    perms = role.permissions
            ^^^^^^^^^^^^^^^^
AttributeError: 'NoneType' object has no attribute 'permissions'

The above exception was the direct cause of the following exception:

Traceback (most recent call last):
  File "C:\Users\Gavin Liles\AppData\Local\Programs\Python\Python313\Lib\site-packages\discord\ext\commands\bot.py", line 1366, in invoke
    await ctx.command.invoke(ctx)
  File "C:\Users\Gavin Liles\AppData\Local\Programs\Python\Python313\Lib\site-packages\discord\ext\commands\core.py", line 1029, in invoke
    await injected(*ctx.args, **ctx.kwargs)  # type: ignore
    ^^^^^^^^^^^^^^^^^^^^^^^^^^^^^^^^^^^^^^^
  File "C:\Users\Gavin Liles\AppData\Local\Programs\Python\Python313\Lib\site-packages\discord\ext\commands\core.py", line 244, in wrapped
    raise CommandInvokeError(exc) from exc
discord.ext.commands.errors.CommandInvokeError: Command raised an exception: AttributeError: 'NoneType' object has no attribute 'permissions'
ERROR:discord.ext.commands.bot:Ignoring exception in command Links
Traceback (most recent call last):
  File "C:\Users\Gavin Liles\AppData\Local\Programs\Python\Python313\Lib\site-packages\discord\ext\commands\core.py", line 235, in wrapped
    ret = await coro(*args, **kwargs)
          ^^^^^^^^^^^^^^^^^^^^^^^^^^^
  File "C:\Users\Gavin Liles\Documents\codeproject\DiscordBot\DiscordBot\main.py", line 101, in Links
    await Commands.Links(ctx, setting)
  File "C:\Users\Gavin Liles\Documents\codeproject\DiscordBot\DiscordBot\Commands.py", line 96, in Links
    perms = role.permissions
            ^^^^^^^^^^^^^^^^
AttributeError: 'NoneType' object has no attribute 'permissions'

The above exception was the direct cause of the following exception:

Traceback (most recent call last):
  File "C:\Users\Gavin Liles\AppData\Local\Programs\Python\Python313\Lib\site-packages\discord\ext\commands\bot.py", line 1366, in invoke
    await ctx.command.invoke(ctx)
  File "C:\Users\Gavin Liles\AppData\Local\Programs\Python\Python313\Lib\site-packages\discord\ext\commands\core.py", line 1029, in invoke
    await injected(*ctx.args, **ctx.kwargs)  # type: ignore
    ^^^^^^^^^^^^^^^^^^^^^^^^^^^^^^^^^^^^^^^
  File "C:\Users\Gavin Liles\AppData\Local\Programs\Python\Python313\Lib\site-packages\discord\ext\commands\core.py", line 244, in wrapped
    raise CommandInvokeError(exc) from exc
discord.ext.commands.errors.CommandInvokeError: Command raised an exception: AttributeError: 'NoneType' object has no attribute 'permissions'
INFO:discord.client:logging in using static token
INFO:slack_bolt.AsyncApp:A new session (s_122352458615) has been established
INFO:slack_bolt.AsyncApp:Bolt app is running!
INFO:discord.gateway:Shard ID None has connected to Gateway (Session ID: c7c29a96dd8abecc810a9e668f2179db).
INFO:discord.client:logging in using static token
INFO:slack_bolt.AsyncApp:A new session (s_147167750007) has been established
INFO:slack_bolt.AsyncApp:Bolt app is running!
INFO:discord.gateway:Shard ID None has connected to Gateway (Session ID: 0465f3f00578883e41d85a6e386c6c3c).
INFO:discord.client:logging in using static token
INFO:slack_bolt.AsyncApp:A new session (s_131449332599) has been established
INFO:slack_bolt.AsyncApp:Bolt app is running!
INFO:discord.gateway:Shard ID None has connected to Gateway (Session ID: 227a9ff637d5b686cb25453cbf82039a).
INFO:discord.client:logging in using static token
INFO:slack_bolt.AsyncApp:A new session (s_94001533815) has been established
INFO:slack_bolt.AsyncApp:Bolt app is running!
INFO:discord.gateway:Shard ID None has connected to Gateway (Session ID: b27326db98ac123ca6b67015a9bc7a69).
INFO:discord.client:logging in using static token
INFO:slack_bolt.AsyncApp:A new session (s_111417209719) has been established
INFO:slack_bolt.AsyncApp:Bolt app is running!
INFO:discord.gateway:Shard ID None has connected to Gateway (Session ID: e36bd510afd1a492660c4c66366a05c6).
WARNING:discord.http:We are being rate limited. POST https://discord.com/api/v10/channels/1377739818234282167/messages/bulk-delete responded with 429. Retrying in 2.93 seconds.
WARNING:discord.http:We are being rate limited. POST https://discord.com/api/v10/channels/1377739818234282167/messages/bulk-delete responded with 429. Retrying in 2.96 seconds.
WARNING:discord.http:We are being rate limited. DELETE https://discord.com/api/v10/channels/1377739818234282167/messages/1395528970769924147 responded with 429. Retrying in 0.30 seconds.
ERROR:discord.ext.commands.bot:Ignoring exception in command Clear
Traceback (most recent call last):
  File "C:\Users\Gavin Liles\AppData\Local\Programs\Python\Python313\Lib\site-packages\discord\ext\commands\core.py", line 235, in wrapped
    ret = await coro(*args, **kwargs)
          ^^^^^^^^^^^^^^^^^^^^^^^^^^^
  File "C:\Users\Gavin Liles\Documents\codeproject\DiscordBot\DiscordBot\main.py", line 105, in Clear
    await Commands.Clear(ctx, amount)
  File "C:\Users\Gavin Liles\Documents\codeproject\DiscordBot\DiscordBot\Commands.py", line 123, in Clear
    #deletes a category, including the channels and roles connected to said category
  File "C:\Users\Gavin Liles\AppData\Local\Programs\Python\Python313\Lib\site-packages\discord\channel.py", line 679, in purge
    return await discord.abc._purge_helper(
           ^^^^^^^^^^^^^^^^^^^^^^^^^^^^^^^^
    ...<9 lines>...
    )
    ^
  File "C:\Users\Gavin Liles\AppData\Local\Programs\Python\Python313\Lib\site-packages\discord\abc.py", line 174, in _purge_helper
    await ret[-1].delete()
  File "C:\Users\Gavin Liles\AppData\Local\Programs\Python\Python313\Lib\site-packages\discord\message.py", line 1304, in delete
    await self._state.http.delete_message(self.channel.id, self.id)
  File "C:\Users\Gavin Liles\AppData\Local\Programs\Python\Python313\Lib\site-packages\discord\http.py", line 758, in request
    raise NotFound(response, data)
discord.errors.NotFound: 404 Not Found (error code: 10008): Unknown Message

The above exception was the direct cause of the following exception:

Traceback (most recent call last):
  File "C:\Users\Gavin Liles\AppData\Local\Programs\Python\Python313\Lib\site-packages\discord\ext\commands\bot.py", line 1366, in invoke
    await ctx.command.invoke(ctx)
  File "C:\Users\Gavin Liles\AppData\Local\Programs\Python\Python313\Lib\site-packages\discord\ext\commands\core.py", line 1029, in invoke
    await injected(*ctx.args, **ctx.kwargs)  # type: ignore
    ^^^^^^^^^^^^^^^^^^^^^^^^^^^^^^^^^^^^^^^
  File "C:\Users\Gavin Liles\AppData\Local\Programs\Python\Python313\Lib\site-packages\discord\ext\commands\core.py", line 244, in wrapped
    raise CommandInvokeError(exc) from exc
discord.ext.commands.errors.CommandInvokeError: Command raised an exception: NotFound: 404 Not Found (error code: 10008): Unknown Message
